Internal Server Error: /users/register/
Traceback (most recent call last):
  File "/Library/Frameworks/Python.framework/Versions/3.13/lib/python3.13/site-packages/django/db/models/query.py", line 948, in get_or_create
    return self.get(**kwargs), False
           ~~~~~~~~^^^^^^^^^^
  File "/Library/Frameworks/Python.framework/Versions/3.13/lib/python3.13/site-packages/django/db/models/query.py", line 649, in get
    raise self.model.DoesNotExist(
        "%s matching query does not exist." % self.model._meta.object_name
    )
users.models.Profile.DoesNotExist: Profile matching query does not exist.

During handling of the above exception, another exception occurred:

Traceback (most recent call last):
  File "/Library/Frameworks/Python.framework/Versions/3.13/lib/python3.13/site-packages/django/core/handlers/exception.py", line 55, in inner
    response = get_response(request)
  File "/Library/Frameworks/Python.framework/Versions/3.13/lib/python3.13/site-packages/django/core/handlers/base.py", line 197, in _get_response
    response = wrapped_callback(request, *callback_args, **callback_kwargs)
  File "/Users/danieloh/ssa_project/users/views.py", line 17, in register
    form.save()
    ~~~~~~~~~^^
  File "/Users/danieloh/ssa_project/users/forms.py", line 22, in save
    user.save()
    ~~~~~~~~~^^
  File "/Library/Frameworks/Python.framework/Versions/3.13/lib/python3.13/site-packages/django/contrib/auth/base_user.py", line 62, in save
    super().save(*args, **kwargs)
    ~~~~~~~~~~~~^^^^^^^^^^^^^^^^^
  File "/Library/Frameworks/Python.framework/Versions/3.13/lib/python3.13/site-packages/django/db/models/base.py", line 891, in save
    self.save_base(
    ~~~~~~~~~~~~~~^
        using=using,
        ^^^^^^^^^^^^
    ...<2 lines>...
        update_fields=update_fields,
        ^^^^^^^^^^^^^^^^^^^^^^^^^^^^
    )
    ^
  File "/Library/Frameworks/Python.framework/Versions/3.13/lib/python3.13/site-packages/django/db/models/base.py", line 1012, in save_base
    post_save.send(
    ~~~~~~~~~~~~~~^
        sender=origin,
        ^^^^^^^^^^^^^^
    ...<4 lines>...
        using=using,
        ^^^^^^^^^^^^
    )
    ^
  File "/Library/Frameworks/Python.framework/Versions/3.13/lib/python3.13/site-packages/django/dispatch/dispatcher.py", line 189, in send
    response = receiver(signal=self, sender=sender, **named)
  File "/Users/danieloh/ssa_project/users/models.py", line 10, in create_user_profile
    Profile.objects.get_or_create(user=instance)  # Safely create the profile without duplicating
    ~~~~~~~~~~~~~~~~~~~~~~~~~~~~~^^^^^^^^^^^^^^^
  File "/Library/Frameworks/Python.framework/Versions/3.13/lib/python3.13/site-packages/django/db/models/manager.py", line 87, in manager_method
    return getattr(self.get_queryset(), name)(*args, **kwargs)
           ~~~~~~~~~~~~~~~~~~~~~~~~~~~~~~~~~~^^^^^^^^^^^^^^^^^
  File "/Library/Frameworks/Python.framework/Versions/3.13/lib/python3.13/site-packages/django/db/models/query.py", line 955, in get_or_create
    return self.create(**params), True
           ~~~~~~~~~~~^^^^^^^^^^
  File "/Library/Frameworks/Python.framework/Versions/3.13/lib/python3.13/site-packages/django/db/models/query.py", line 679, in create
    obj.save(force_insert=True, using=self.db)
    ~~~~~~~~^^^^^^^^^^^^^^^^^^^^^^^^^^^^^^^^^^
  File "/Users/danieloh/ssa_project/users/models.py", line 36, in save
    self.clean()
    ~~~~~~~~~~^^
  File "/Users/danieloh/ssa_project/users/models.py", line 33, in clean
    validate_unique_nickname(self.nickname, instance=self)
    ~~~~~~~~~~~~~~~~~~~~~~~~^^^^^^^^^^^^^^^^^^^^^^^^^^^^^^
  File "/Users/danieloh/ssa_project/users/models.py", line 21, in validate_unique_nickname
    raise ValidationError(f"Nickname '{nickname}' is already taken.")
django.core.exceptions.ValidationError: ["Nickname '' is already taken."]
"POST /users/register/ HTTP/1.1" 500 123701
