Internal Server Error: /users/register/
Traceback (most recent call last):
  File "/Library/Frameworks/Python.framework/Versions/3.13/lib/python3.13/site-packages/django/db/models/query.py", line 948, in get_or_create
    return self.get(**kwargs), False
           ~~~~~~~~^^^^^^^^^^
  File "/Library/Frameworks/Python.framework/Versions/3.13/lib/python3.13/site-packages/django/db/models/query.py", line 649, in get
    raise self.model.DoesNotExist(
        "%s matching query does not exist." % self.model._meta.object_name
    )
users.models.Profile.DoesNotExist: Profile matching query does not exist.

During handling of the above exception, another exception occurred:

Traceback (most recent call last):
  File "/Library/Frameworks/Python.framework/Versions/3.13/lib/python3.13/site-packages/django/core/handlers/exception.py", line 55, in inner
    response = get_response(request)
  File "/Library/Frameworks/Python.framework/Versions/3.13/lib/python3.13/site-packages/django/core/handlers/base.py", line 197, in _get_response
    response = wrapped_callback(request, *callback_args, **callback_kwargs)
  File "/Users/danieloh/ssa_project/users/views.py", line 17, in register
    form.save()
    ~~~~~~~~~^^
  File "/Users/danieloh/ssa_project/users/forms.py", line 22, in save
    user.save()
    ~~~~~~~~~^^
  File "/Library/Frameworks/Python.framework/Versions/3.13/lib/python3.13/site-packages/django/contrib/auth/base_user.py", line 62, in save
    super().save(*args, **kwargs)
    ~~~~~~~~~~~~^^^^^^^^^^^^^^^^^
  File "/Library/Frameworks/Python.framework/Versions/3.13/lib/python3.13/site-packages/django/db/models/base.py", line 891, in save
    self.save_base(
    ~~~~~~~~~~~~~~^
        using=using,
        ^^^^^^^^^^^^
    ...<2 lines>...
        update_fields=update_fields,
        ^^^^^^^^^^^^^^^^^^^^^^^^^^^^
    )
    ^
  File "/Library/Frameworks/Python.framework/Versions/3.13/lib/python3.13/site-packages/django/db/models/base.py", line 1012, in save_base
    post_save.send(
    ~~~~~~~~~~~~~~^
        sender=origin,
        ^^^^^^^^^^^^^^
    ...<4 lines>...
        using=using,
        ^^^^^^^^^^^^
    )
    ^
  File "/Library/Frameworks/Python.framework/Versions/3.13/lib/python3.13/site-packages/django/dispatch/dispatcher.py", line 189, in send
    response = receiver(signal=self, sender=sender, **named)
  File "/Users/danieloh/ssa_project/users/models.py", line 10, in create_user_profile
    Profile.objects.get_or_create(user=instance)  # Safely create the profile without duplicating
    ~~~~~~~~~~~~~~~~~~~~~~~~~~~~~^^^^^^^^^^^^^^^
  File "/Library/Frameworks/Python.framework/Versions/3.13/lib/python3.13/site-packages/django/db/models/manager.py", line 87, in manager_method
    return getattr(self.get_queryset(), name)(*args, **kwargs)
           ~~~~~~~~~~~~~~~~~~~~~~~~~~~~~~~~~~^^^^^^^^^^^^^^^^^
  File "/Library/Frameworks/Python.framework/Versions/3.13/lib/python3.13/site-packages/django/db/models/query.py", line 955, in get_or_create
    return self.create(**params), True
           ~~~~~~~~~~~^^^^^^^^^^
  File "/Library/Frameworks/Python.framework/Versions/3.13/lib/python3.13/site-packages/django/db/models/query.py", line 679, in create
    obj.save(force_insert=True, using=self.db)
    ~~~~~~~~^^^^^^^^^^^^^^^^^^^^^^^^^^^^^^^^^^
  File "/Users/danieloh/ssa_project/users/models.py", line 36, in save
    self.clean()
    ~~~~~~~~~~^^
  File "/Users/danieloh/ssa_project/users/models.py", line 33, in clean
    validate_unique_nickname(self.nickname, instance=self)
    ~~~~~~~~~~~~~~~~~~~~~~~~^^^^^^^^^^^^^^^^^^^^^^^^^^^^^^
  File "/Users/danieloh/ssa_project/users/models.py", line 21, in validate_unique_nickname
    raise ValidationError(f"Nickname '{nickname}' is already taken.")
django.core.exceptions.ValidationError: ["Nickname '' is already taken."]
"POST /users/register/ HTTP/1.1" 500 123701
Internal Server Error: /users/register/
Traceback (most recent call last):
  File "/Library/Frameworks/Python.framework/Versions/3.13/lib/python3.13/site-packages/django/db/models/query.py", line 948, in get_or_create
    return self.get(**kwargs), False
           ~~~~~~~~^^^^^^^^^^
  File "/Library/Frameworks/Python.framework/Versions/3.13/lib/python3.13/site-packages/django/db/models/query.py", line 649, in get
    raise self.model.DoesNotExist(
        "%s matching query does not exist." % self.model._meta.object_name
    )
users.models.Profile.DoesNotExist: Profile matching query does not exist.

During handling of the above exception, another exception occurred:

Traceback (most recent call last):
  File "/Library/Frameworks/Python.framework/Versions/3.13/lib/python3.13/site-packages/django/core/handlers/exception.py", line 55, in inner
    response = get_response(request)
  File "/Library/Frameworks/Python.framework/Versions/3.13/lib/python3.13/site-packages/django/core/handlers/base.py", line 197, in _get_response
    response = wrapped_callback(request, *callback_args, **callback_kwargs)
  File "/Users/danieloh/ssa_project/users/views.py", line 17, in register
    form.save()
    ~~~~~~~~~^^
  File "/Users/danieloh/ssa_project/users/forms.py", line 22, in save
    user.save()
    ~~~~~~~~~^^
  File "/Library/Frameworks/Python.framework/Versions/3.13/lib/python3.13/site-packages/django/contrib/auth/base_user.py", line 62, in save
    super().save(*args, **kwargs)
    ~~~~~~~~~~~~^^^^^^^^^^^^^^^^^
  File "/Library/Frameworks/Python.framework/Versions/3.13/lib/python3.13/site-packages/django/db/models/base.py", line 891, in save
    self.save_base(
    ~~~~~~~~~~~~~~^
        using=using,
        ^^^^^^^^^^^^
    ...<2 lines>...
        update_fields=update_fields,
        ^^^^^^^^^^^^^^^^^^^^^^^^^^^^
    )
    ^
  File "/Library/Frameworks/Python.framework/Versions/3.13/lib/python3.13/site-packages/django/db/models/base.py", line 1012, in save_base
    post_save.send(
    ~~~~~~~~~~~~~~^
        sender=origin,
        ^^^^^^^^^^^^^^
    ...<4 lines>...
        using=using,
        ^^^^^^^^^^^^
    )
    ^
  File "/Library/Frameworks/Python.framework/Versions/3.13/lib/python3.13/site-packages/django/dispatch/dispatcher.py", line 189, in send
    response = receiver(signal=self, sender=sender, **named)
  File "/Users/danieloh/ssa_project/users/models.py", line 10, in create_user_profile
    Profile.objects.get_or_create(user=instance)  # Safely create the profile without duplicating
    ~~~~~~~~~~~~~~~~~~~~~~~~~~~~~^^^^^^^^^^^^^^^
  File "/Library/Frameworks/Python.framework/Versions/3.13/lib/python3.13/site-packages/django/db/models/manager.py", line 87, in manager_method
    return getattr(self.get_queryset(), name)(*args, **kwargs)
           ~~~~~~~~~~~~~~~~~~~~~~~~~~~~~~~~~~^^^^^^^^^^^^^^^^^
  File "/Library/Frameworks/Python.framework/Versions/3.13/lib/python3.13/site-packages/django/db/models/query.py", line 955, in get_or_create
    return self.create(**params), True
           ~~~~~~~~~~~^^^^^^^^^^
  File "/Library/Frameworks/Python.framework/Versions/3.13/lib/python3.13/site-packages/django/db/models/query.py", line 679, in create
    obj.save(force_insert=True, using=self.db)
    ~~~~~~~~^^^^^^^^^^^^^^^^^^^^^^^^^^^^^^^^^^
  File "/Users/danieloh/ssa_project/users/models.py", line 36, in save
    self.clean()
    ~~~~~~~~~~^^
  File "/Users/danieloh/ssa_project/users/models.py", line 33, in clean
    validate_unique_nickname(self.nickname, instance=self)
    ~~~~~~~~~~~~~~~~~~~~~~~~^^^^^^^^^^^^^^^^^^^^^^^^^^^^^^
  File "/Users/danieloh/ssa_project/users/models.py", line 21, in validate_unique_nickname
    raise ValidationError(f"Nickname '{nickname}' is already taken.")
django.core.exceptions.ValidationError: ["Nickname '' is already taken."]
"POST /users/register/ HTTP/1.1" 500 123576
Internal Server Error: /users/register/
Traceback (most recent call last):
  File "/Library/Frameworks/Python.framework/Versions/3.13/lib/python3.13/site-packages/django/db/models/query.py", line 948, in get_or_create
    return self.get(**kwargs), False
           ~~~~~~~~^^^^^^^^^^
  File "/Library/Frameworks/Python.framework/Versions/3.13/lib/python3.13/site-packages/django/db/models/query.py", line 649, in get
    raise self.model.DoesNotExist(
        "%s matching query does not exist." % self.model._meta.object_name
    )
users.models.Profile.DoesNotExist: Profile matching query does not exist.

During handling of the above exception, another exception occurred:

Traceback (most recent call last):
  File "/Library/Frameworks/Python.framework/Versions/3.13/lib/python3.13/site-packages/django/core/handlers/exception.py", line 55, in inner
    response = get_response(request)
  File "/Library/Frameworks/Python.framework/Versions/3.13/lib/python3.13/site-packages/django/core/handlers/base.py", line 197, in _get_response
    response = wrapped_callback(request, *callback_args, **callback_kwargs)
  File "/Users/danieloh/ssa_project/users/views.py", line 17, in register
    form.save()
    ~~~~~~~~~^^
  File "/Users/danieloh/ssa_project/users/forms.py", line 22, in save
    user.save()
    ~~~~~~~~~^^
  File "/Library/Frameworks/Python.framework/Versions/3.13/lib/python3.13/site-packages/django/contrib/auth/base_user.py", line 62, in save
    super().save(*args, **kwargs)
    ~~~~~~~~~~~~^^^^^^^^^^^^^^^^^
  File "/Library/Frameworks/Python.framework/Versions/3.13/lib/python3.13/site-packages/django/db/models/base.py", line 891, in save
    self.save_base(
    ~~~~~~~~~~~~~~^
        using=using,
        ^^^^^^^^^^^^
    ...<2 lines>...
        update_fields=update_fields,
        ^^^^^^^^^^^^^^^^^^^^^^^^^^^^
    )
    ^
  File "/Library/Frameworks/Python.framework/Versions/3.13/lib/python3.13/site-packages/django/db/models/base.py", line 1012, in save_base
    post_save.send(
    ~~~~~~~~~~~~~~^
        sender=origin,
        ^^^^^^^^^^^^^^
    ...<4 lines>...
        using=using,
        ^^^^^^^^^^^^
    )
    ^
  File "/Library/Frameworks/Python.framework/Versions/3.13/lib/python3.13/site-packages/django/dispatch/dispatcher.py", line 189, in send
    response = receiver(signal=self, sender=sender, **named)
  File "/Users/danieloh/ssa_project/users/models.py", line 10, in create_user_profile
    Profile.objects.get_or_create(user=instance)  # Safely create the profile without duplicating
    ~~~~~~~~~~~~~~~~~~~~~~~~~~~~~^^^^^^^^^^^^^^^
  File "/Library/Frameworks/Python.framework/Versions/3.13/lib/python3.13/site-packages/django/db/models/manager.py", line 87, in manager_method
    return getattr(self.get_queryset(), name)(*args, **kwargs)
           ~~~~~~~~~~~~~~~~~~~~~~~~~~~~~~~~~~^^^^^^^^^^^^^^^^^
  File "/Library/Frameworks/Python.framework/Versions/3.13/lib/python3.13/site-packages/django/db/models/query.py", line 955, in get_or_create
    return self.create(**params), True
           ~~~~~~~~~~~^^^^^^^^^^
  File "/Library/Frameworks/Python.framework/Versions/3.13/lib/python3.13/site-packages/django/db/models/query.py", line 679, in create
    obj.save(force_insert=True, using=self.db)
    ~~~~~~~~^^^^^^^^^^^^^^^^^^^^^^^^^^^^^^^^^^
  File "/Users/danieloh/ssa_project/users/models.py", line 36, in save
    self.clean()
    ~~~~~~~~~~^^
  File "/Users/danieloh/ssa_project/users/models.py", line 33, in clean
    validate_unique_nickname(self.nickname, instance=self)
    ~~~~~~~~~~~~~~~~~~~~~~~~^^^^^^^^^^^^^^^^^^^^^^^^^^^^^^
  File "/Users/danieloh/ssa_project/users/models.py", line 21, in validate_unique_nickname
    raise ValidationError(f"Nickname '{nickname}' is already taken.")
django.core.exceptions.ValidationError: ["Nickname '' is already taken."]
"POST /users/register/ HTTP/1.1" 500 123610
Internal Server Error: /users/register/
Traceback (most recent call last):
  File "/Library/Frameworks/Python.framework/Versions/3.13/lib/python3.13/site-packages/django/db/models/query.py", line 948, in get_or_create
    return self.get(**kwargs), False
           ~~~~~~~~^^^^^^^^^^
  File "/Library/Frameworks/Python.framework/Versions/3.13/lib/python3.13/site-packages/django/db/models/query.py", line 649, in get
    raise self.model.DoesNotExist(
        "%s matching query does not exist." % self.model._meta.object_name
    )
users.models.Profile.DoesNotExist: Profile matching query does not exist.

During handling of the above exception, another exception occurred:

Traceback (most recent call last):
  File "/Library/Frameworks/Python.framework/Versions/3.13/lib/python3.13/site-packages/django/core/handlers/exception.py", line 55, in inner
    response = get_response(request)
  File "/Library/Frameworks/Python.framework/Versions/3.13/lib/python3.13/site-packages/django/core/handlers/base.py", line 197, in _get_response
    response = wrapped_callback(request, *callback_args, **callback_kwargs)
  File "/Users/danieloh/ssa_project/users/views.py", line 17, in register
    form.save()
    ~~~~~~~~~^^
  File "/Users/danieloh/ssa_project/users/forms.py", line 22, in save
    user.save()
    ~~~~~~~~~^^
  File "/Library/Frameworks/Python.framework/Versions/3.13/lib/python3.13/site-packages/django/contrib/auth/base_user.py", line 62, in save
    super().save(*args, **kwargs)
    ~~~~~~~~~~~~^^^^^^^^^^^^^^^^^
  File "/Library/Frameworks/Python.framework/Versions/3.13/lib/python3.13/site-packages/django/db/models/base.py", line 891, in save
    self.save_base(
    ~~~~~~~~~~~~~~^
        using=using,
        ^^^^^^^^^^^^
    ...<2 lines>...
        update_fields=update_fields,
        ^^^^^^^^^^^^^^^^^^^^^^^^^^^^
    )
    ^
  File "/Library/Frameworks/Python.framework/Versions/3.13/lib/python3.13/site-packages/django/db/models/base.py", line 1012, in save_base
    post_save.send(
    ~~~~~~~~~~~~~~^
        sender=origin,
        ^^^^^^^^^^^^^^
    ...<4 lines>...
        using=using,
        ^^^^^^^^^^^^
    )
    ^
  File "/Library/Frameworks/Python.framework/Versions/3.13/lib/python3.13/site-packages/django/dispatch/dispatcher.py", line 189, in send
    response = receiver(signal=self, sender=sender, **named)
  File "/Users/danieloh/ssa_project/users/models.py", line 11, in manage_user_profile
    Profile.objects.get_or_create(user=instance)
    ~~~~~~~~~~~~~~~~~~~~~~~~~~~~~^^^^^^^^^^^^^^^
  File "/Library/Frameworks/Python.framework/Versions/3.13/lib/python3.13/site-packages/django/db/models/manager.py", line 87, in manager_method
    return getattr(self.get_queryset(), name)(*args, **kwargs)
           ~~~~~~~~~~~~~~~~~~~~~~~~~~~~~~~~~~^^^^^^^^^^^^^^^^^
  File "/Library/Frameworks/Python.framework/Versions/3.13/lib/python3.13/site-packages/django/db/models/query.py", line 955, in get_or_create
    return self.create(**params), True
           ~~~~~~~~~~~^^^^^^^^^^
  File "/Library/Frameworks/Python.framework/Versions/3.13/lib/python3.13/site-packages/django/db/models/query.py", line 679, in create
    obj.save(force_insert=True, using=self.db)
    ~~~~~~~~^^^^^^^^^^^^^^^^^^^^^^^^^^^^^^^^^^
  File "/Users/danieloh/ssa_project/users/models.py", line 34, in save
    self.clean()
    ~~~~~~~~~~^^
  File "/Users/danieloh/ssa_project/users/models.py", line 31, in clean
    validate_unique_nickname(self.nickname, instance=self)
    ~~~~~~~~~~~~~~~~~~~~~~~~^^^^^^^^^^^^^^^^^^^^^^^^^^^^^^
  File "/Users/danieloh/ssa_project/users/models.py", line 21, in validate_unique_nickname
    raise ValidationError(f"Nickname '{nickname}' is already taken.")
django.core.exceptions.ValidationError: ["Nickname '' is already taken."]
"POST /users/register/ HTTP/1.1" 500 123373
Internal Server Error: /users/register/
Traceback (most recent call last):
  File "/Library/Frameworks/Python.framework/Versions/3.13/lib/python3.13/site-packages/django/db/models/query.py", line 948, in get_or_create
    return self.get(**kwargs), False
           ~~~~~~~~^^^^^^^^^^
  File "/Library/Frameworks/Python.framework/Versions/3.13/lib/python3.13/site-packages/django/db/models/query.py", line 649, in get
    raise self.model.DoesNotExist(
        "%s matching query does not exist." % self.model._meta.object_name
    )
users.models.Profile.DoesNotExist: Profile matching query does not exist.

During handling of the above exception, another exception occurred:

Traceback (most recent call last):
  File "/Library/Frameworks/Python.framework/Versions/3.13/lib/python3.13/site-packages/django/core/handlers/exception.py", line 55, in inner
    response = get_response(request)
  File "/Library/Frameworks/Python.framework/Versions/3.13/lib/python3.13/site-packages/django/core/handlers/base.py", line 197, in _get_response
    response = wrapped_callback(request, *callback_args, **callback_kwargs)
  File "/Users/danieloh/ssa_project/users/views.py", line 17, in register
    form.save()
    ~~~~~~~~~^^
  File "/Users/danieloh/ssa_project/users/forms.py", line 22, in save
    user.save()
    ~~~~~~~~~^^
  File "/Library/Frameworks/Python.framework/Versions/3.13/lib/python3.13/site-packages/django/contrib/auth/base_user.py", line 62, in save
    super().save(*args, **kwargs)
    ~~~~~~~~~~~~^^^^^^^^^^^^^^^^^
  File "/Library/Frameworks/Python.framework/Versions/3.13/lib/python3.13/site-packages/django/db/models/base.py", line 891, in save
    self.save_base(
    ~~~~~~~~~~~~~~^
        using=using,
        ^^^^^^^^^^^^
    ...<2 lines>...
        update_fields=update_fields,
        ^^^^^^^^^^^^^^^^^^^^^^^^^^^^
    )
    ^
  File "/Library/Frameworks/Python.framework/Versions/3.13/lib/python3.13/site-packages/django/db/models/base.py", line 1012, in save_base
    post_save.send(
    ~~~~~~~~~~~~~~^
        sender=origin,
        ^^^^^^^^^^^^^^
    ...<4 lines>...
        using=using,
        ^^^^^^^^^^^^
    )
    ^
  File "/Library/Frameworks/Python.framework/Versions/3.13/lib/python3.13/site-packages/django/dispatch/dispatcher.py", line 189, in send
    response = receiver(signal=self, sender=sender, **named)
  File "/Users/danieloh/ssa_project/users/models.py", line 10, in create_user_profile
    Profile.objects.get_or_create(user=instance)  # Safely create the profile without duplicating
    ~~~~~~~~~~~~~~~~~~~~~~~~~~~~~^^^^^^^^^^^^^^^
  File "/Library/Frameworks/Python.framework/Versions/3.13/lib/python3.13/site-packages/django/db/models/manager.py", line 87, in manager_method
    return getattr(self.get_queryset(), name)(*args, **kwargs)
           ~~~~~~~~~~~~~~~~~~~~~~~~~~~~~~~~~~^^^^^^^^^^^^^^^^^
  File "/Library/Frameworks/Python.framework/Versions/3.13/lib/python3.13/site-packages/django/db/models/query.py", line 955, in get_or_create
    return self.create(**params), True
           ~~~~~~~~~~~^^^^^^^^^^
  File "/Library/Frameworks/Python.framework/Versions/3.13/lib/python3.13/site-packages/django/db/models/query.py", line 679, in create
    obj.save(force_insert=True, using=self.db)
    ~~~~~~~~^^^^^^^^^^^^^^^^^^^^^^^^^^^^^^^^^^
  File "/Users/danieloh/ssa_project/users/models.py", line 36, in save
    self.clean()
    ~~~~~~~~~~^^
  File "/Users/danieloh/ssa_project/users/models.py", line 33, in clean
    validate_unique_nickname(self.nickname, instance=self)
    ~~~~~~~~~~~~~~~~~~~~~~~~^^^^^^^^^^^^^^^^^^^^^^^^^^^^^^
  File "/Users/danieloh/ssa_project/users/models.py", line 21, in validate_unique_nickname
    raise ValidationError(f"Nickname '{nickname}' is already taken.")
django.core.exceptions.ValidationError: ["Nickname '' is already taken."]
"POST /users/register/ HTTP/1.1" 500 123667
Internal Server Error: /users/register/
Traceback (most recent call last):
  File "/Library/Frameworks/Python.framework/Versions/3.13/lib/python3.13/site-packages/django/db/models/query.py", line 948, in get_or_create
    return self.get(**kwargs), False
           ~~~~~~~~^^^^^^^^^^
  File "/Library/Frameworks/Python.framework/Versions/3.13/lib/python3.13/site-packages/django/db/models/query.py", line 649, in get
    raise self.model.DoesNotExist(
        "%s matching query does not exist." % self.model._meta.object_name
    )
users.models.Profile.DoesNotExist: Profile matching query does not exist.

During handling of the above exception, another exception occurred:

Traceback (most recent call last):
  File "/Library/Frameworks/Python.framework/Versions/3.13/lib/python3.13/site-packages/django/core/handlers/exception.py", line 55, in inner
    response = get_response(request)
  File "/Library/Frameworks/Python.framework/Versions/3.13/lib/python3.13/site-packages/django/core/handlers/base.py", line 197, in _get_response
    response = wrapped_callback(request, *callback_args, **callback_kwargs)
  File "/Users/danieloh/ssa_project/users/views.py", line 17, in register
    form.save()
    ~~~~~~~~~^^
  File "/Users/danieloh/ssa_project/users/forms.py", line 22, in save
    user.save()
    ~~~~~~~~~^^
  File "/Library/Frameworks/Python.framework/Versions/3.13/lib/python3.13/site-packages/django/contrib/auth/base_user.py", line 62, in save
    super().save(*args, **kwargs)
    ~~~~~~~~~~~~^^^^^^^^^^^^^^^^^
  File "/Library/Frameworks/Python.framework/Versions/3.13/lib/python3.13/site-packages/django/db/models/base.py", line 891, in save
    self.save_base(
    ~~~~~~~~~~~~~~^
        using=using,
        ^^^^^^^^^^^^
    ...<2 lines>...
        update_fields=update_fields,
        ^^^^^^^^^^^^^^^^^^^^^^^^^^^^
    )
    ^
  File "/Library/Frameworks/Python.framework/Versions/3.13/lib/python3.13/site-packages/django/db/models/base.py", line 1012, in save_base
    post_save.send(
    ~~~~~~~~~~~~~~^
        sender=origin,
        ^^^^^^^^^^^^^^
    ...<4 lines>...
        using=using,
        ^^^^^^^^^^^^
    )
    ^
  File "/Library/Frameworks/Python.framework/Versions/3.13/lib/python3.13/site-packages/django/dispatch/dispatcher.py", line 189, in send
    response = receiver(signal=self, sender=sender, **named)
  File "/Users/danieloh/ssa_project/users/models.py", line 10, in create_user_profile
    Profile.objects.get_or_create(user=instance)  # Safely create the profile without duplicating
    ~~~~~~~~~~~~~~~~~~~~~~~~~~~~~^^^^^^^^^^^^^^^
  File "/Library/Frameworks/Python.framework/Versions/3.13/lib/python3.13/site-packages/django/db/models/manager.py", line 87, in manager_method
    return getattr(self.get_queryset(), name)(*args, **kwargs)
           ~~~~~~~~~~~~~~~~~~~~~~~~~~~~~~~~~~^^^^^^^^^^^^^^^^^
  File "/Library/Frameworks/Python.framework/Versions/3.13/lib/python3.13/site-packages/django/db/models/query.py", line 955, in get_or_create
    return self.create(**params), True
           ~~~~~~~~~~~^^^^^^^^^^
  File "/Library/Frameworks/Python.framework/Versions/3.13/lib/python3.13/site-packages/django/db/models/query.py", line 679, in create
    obj.save(force_insert=True, using=self.db)
    ~~~~~~~~^^^^^^^^^^^^^^^^^^^^^^^^^^^^^^^^^^
  File "/Users/danieloh/ssa_project/users/models.py", line 36, in save
    self.clean()
    ~~~~~~~~~~^^
  File "/Users/danieloh/ssa_project/users/models.py", line 33, in clean
    validate_unique_nickname(self.nickname, instance=self)
    ~~~~~~~~~~~~~~~~~~~~~~~~^^^^^^^^^^^^^^^^^^^^^^^^^^^^^^
  File "/Users/danieloh/ssa_project/users/models.py", line 21, in validate_unique_nickname
    raise ValidationError(f"Nickname '{nickname}' is already taken.")
django.core.exceptions.ValidationError: ["Nickname '' is already taken."]
"POST /users/register/ HTTP/1.1" 500 123660
Internal Server Error: /users/register/
Traceback (most recent call last):
  File "/Library/Frameworks/Python.framework/Versions/3.13/lib/python3.13/site-packages/django/db/models/query.py", line 948, in get_or_create
    return self.get(**kwargs), False
           ~~~~~~~~^^^^^^^^^^
  File "/Library/Frameworks/Python.framework/Versions/3.13/lib/python3.13/site-packages/django/db/models/query.py", line 649, in get
    raise self.model.DoesNotExist(
        "%s matching query does not exist." % self.model._meta.object_name
    )
users.models.Profile.DoesNotExist: Profile matching query does not exist.

During handling of the above exception, another exception occurred:

Traceback (most recent call last):
  File "/Library/Frameworks/Python.framework/Versions/3.13/lib/python3.13/site-packages/django/core/handlers/exception.py", line 55, in inner
    response = get_response(request)
  File "/Library/Frameworks/Python.framework/Versions/3.13/lib/python3.13/site-packages/django/core/handlers/base.py", line 197, in _get_response
    response = wrapped_callback(request, *callback_args, **callback_kwargs)
  File "/Users/danieloh/ssa_project/users/views.py", line 17, in register
    form.save()
    ~~~~~~~~~^^
  File "/Users/danieloh/ssa_project/users/forms.py", line 22, in save
    user.save()
    ~~~~~~~~~^^
  File "/Library/Frameworks/Python.framework/Versions/3.13/lib/python3.13/site-packages/django/contrib/auth/base_user.py", line 62, in save
    super().save(*args, **kwargs)
    ~~~~~~~~~~~~^^^^^^^^^^^^^^^^^
  File "/Library/Frameworks/Python.framework/Versions/3.13/lib/python3.13/site-packages/django/db/models/base.py", line 891, in save
    self.save_base(
    ~~~~~~~~~~~~~~^
        using=using,
        ^^^^^^^^^^^^
    ...<2 lines>...
        update_fields=update_fields,
        ^^^^^^^^^^^^^^^^^^^^^^^^^^^^
    )
    ^
  File "/Library/Frameworks/Python.framework/Versions/3.13/lib/python3.13/site-packages/django/db/models/base.py", line 1012, in save_base
    post_save.send(
    ~~~~~~~~~~~~~~^
        sender=origin,
        ^^^^^^^^^^^^^^
    ...<4 lines>...
        using=using,
        ^^^^^^^^^^^^
    )
    ^
  File "/Library/Frameworks/Python.framework/Versions/3.13/lib/python3.13/site-packages/django/dispatch/dispatcher.py", line 189, in send
    response = receiver(signal=self, sender=sender, **named)
  File "/Users/danieloh/ssa_project/users/models.py", line 10, in create_user_profile
    Profile.objects.get_or_create(user=instance)  # Safely create the profile without duplicating
    ~~~~~~~~~~~~~~~~~~~~~~~~~~~~~^^^^^^^^^^^^^^^
  File "/Library/Frameworks/Python.framework/Versions/3.13/lib/python3.13/site-packages/django/db/models/manager.py", line 87, in manager_method
    return getattr(self.get_queryset(), name)(*args, **kwargs)
           ~~~~~~~~~~~~~~~~~~~~~~~~~~~~~~~~~~^^^^^^^^^^^^^^^^^
  File "/Library/Frameworks/Python.framework/Versions/3.13/lib/python3.13/site-packages/django/db/models/query.py", line 955, in get_or_create
    return self.create(**params), True
           ~~~~~~~~~~~^^^^^^^^^^
  File "/Library/Frameworks/Python.framework/Versions/3.13/lib/python3.13/site-packages/django/db/models/query.py", line 679, in create
    obj.save(force_insert=True, using=self.db)
    ~~~~~~~~^^^^^^^^^^^^^^^^^^^^^^^^^^^^^^^^^^
  File "/Users/danieloh/ssa_project/users/models.py", line 36, in save
    self.clean()
    ~~~~~~~~~~^^
  File "/Users/danieloh/ssa_project/users/models.py", line 33, in clean
    validate_unique_nickname(self.nickname, instance=self)
    ~~~~~~~~~~~~~~~~~~~~~~~~^^^^^^^^^^^^^^^^^^^^^^^^^^^^^^
  File "/Users/danieloh/ssa_project/users/models.py", line 21, in validate_unique_nickname
    raise ValidationError(f"Nickname '{nickname}' is already taken.")
django.core.exceptions.ValidationError: ["Nickname '' is already taken."]
"POST /users/register/ HTTP/1.1" 500 123578
Internal Server Error: /users/register/
Traceback (most recent call last):
  File "/Library/Frameworks/Python.framework/Versions/3.13/lib/python3.13/site-packages/django/db/models/query.py", line 948, in get_or_create
    return self.get(**kwargs), False
           ~~~~~~~~^^^^^^^^^^
  File "/Library/Frameworks/Python.framework/Versions/3.13/lib/python3.13/site-packages/django/db/models/query.py", line 649, in get
    raise self.model.DoesNotExist(
        "%s matching query does not exist." % self.model._meta.object_name
    )
users.models.Profile.DoesNotExist: Profile matching query does not exist.

During handling of the above exception, another exception occurred:

Traceback (most recent call last):
  File "/Library/Frameworks/Python.framework/Versions/3.13/lib/python3.13/site-packages/django/core/handlers/exception.py", line 55, in inner
    response = get_response(request)
  File "/Library/Frameworks/Python.framework/Versions/3.13/lib/python3.13/site-packages/django/core/handlers/base.py", line 197, in _get_response
    response = wrapped_callback(request, *callback_args, **callback_kwargs)
  File "/Users/danieloh/ssa_project/users/views.py", line 17, in register
    form.save()
    ~~~~~~~~~^^
  File "/Users/danieloh/ssa_project/users/forms.py", line 22, in save
    user.save()
    ~~~~~~~~~^^
  File "/Library/Frameworks/Python.framework/Versions/3.13/lib/python3.13/site-packages/django/contrib/auth/base_user.py", line 62, in save
    super().save(*args, **kwargs)
    ~~~~~~~~~~~~^^^^^^^^^^^^^^^^^
  File "/Library/Frameworks/Python.framework/Versions/3.13/lib/python3.13/site-packages/django/db/models/base.py", line 891, in save
    self.save_base(
    ~~~~~~~~~~~~~~^
        using=using,
        ^^^^^^^^^^^^
    ...<2 lines>...
        update_fields=update_fields,
        ^^^^^^^^^^^^^^^^^^^^^^^^^^^^
    )
    ^
  File "/Library/Frameworks/Python.framework/Versions/3.13/lib/python3.13/site-packages/django/db/models/base.py", line 1012, in save_base
    post_save.send(
    ~~~~~~~~~~~~~~^
        sender=origin,
        ^^^^^^^^^^^^^^
    ...<4 lines>...
        using=using,
        ^^^^^^^^^^^^
    )
    ^
  File "/Library/Frameworks/Python.framework/Versions/3.13/lib/python3.13/site-packages/django/dispatch/dispatcher.py", line 189, in send
    response = receiver(signal=self, sender=sender, **named)
  File "/Users/danieloh/ssa_project/users/models.py", line 10, in create_user_profile
    Profile.objects.get_or_create(user=instance)  # Safely create the profile without duplicating
    ~~~~~~~~~~~~~~~~~~~~~~~~~~~~~^^^^^^^^^^^^^^^
  File "/Library/Frameworks/Python.framework/Versions/3.13/lib/python3.13/site-packages/django/db/models/manager.py", line 87, in manager_method
    return getattr(self.get_queryset(), name)(*args, **kwargs)
           ~~~~~~~~~~~~~~~~~~~~~~~~~~~~~~~~~~^^^^^^^^^^^^^^^^^
  File "/Library/Frameworks/Python.framework/Versions/3.13/lib/python3.13/site-packages/django/db/models/query.py", line 955, in get_or_create
    return self.create(**params), True
           ~~~~~~~~~~~^^^^^^^^^^
  File "/Library/Frameworks/Python.framework/Versions/3.13/lib/python3.13/site-packages/django/db/models/query.py", line 679, in create
    obj.save(force_insert=True, using=self.db)
    ~~~~~~~~^^^^^^^^^^^^^^^^^^^^^^^^^^^^^^^^^^
  File "/Users/danieloh/ssa_project/users/models.py", line 36, in save
    self.clean()
    ~~~~~~~~~~^^
  File "/Users/danieloh/ssa_project/users/models.py", line 33, in clean
    validate_unique_nickname(self.nickname, instance=self)
    ~~~~~~~~~~~~~~~~~~~~~~~~^^^^^^^^^^^^^^^^^^^^^^^^^^^^^^
  File "/Users/danieloh/ssa_project/users/models.py", line 21, in validate_unique_nickname
    raise ValidationError(f"Nickname '{nickname}' is already taken.")
django.core.exceptions.ValidationError: ["Nickname '' is already taken."]
"POST /users/register/ HTTP/1.1" 500 123647
Internal Server Error: /users/register/
Traceback (most recent call last):
  File "/Library/Frameworks/Python.framework/Versions/3.13/lib/python3.13/site-packages/django/db/models/query.py", line 948, in get_or_create
    return self.get(**kwargs), False
           ~~~~~~~~^^^^^^^^^^
  File "/Library/Frameworks/Python.framework/Versions/3.13/lib/python3.13/site-packages/django/db/models/query.py", line 649, in get
    raise self.model.DoesNotExist(
        "%s matching query does not exist." % self.model._meta.object_name
    )
users.models.Profile.DoesNotExist: Profile matching query does not exist.

During handling of the above exception, another exception occurred:

Traceback (most recent call last):
  File "/Library/Frameworks/Python.framework/Versions/3.13/lib/python3.13/site-packages/django/core/handlers/exception.py", line 55, in inner
    response = get_response(request)
  File "/Library/Frameworks/Python.framework/Versions/3.13/lib/python3.13/site-packages/django/core/handlers/base.py", line 197, in _get_response
    response = wrapped_callback(request, *callback_args, **callback_kwargs)
  File "/Users/danieloh/ssa_project/users/views.py", line 17, in register
    form.save()
    ~~~~~~~~~^^
  File "/Users/danieloh/ssa_project/users/forms.py", line 22, in save
    user.save()
    ~~~~~~~~~^^
  File "/Library/Frameworks/Python.framework/Versions/3.13/lib/python3.13/site-packages/django/contrib/auth/base_user.py", line 62, in save
    super().save(*args, **kwargs)
    ~~~~~~~~~~~~^^^^^^^^^^^^^^^^^
  File "/Library/Frameworks/Python.framework/Versions/3.13/lib/python3.13/site-packages/django/db/models/base.py", line 891, in save
    self.save_base(
    ~~~~~~~~~~~~~~^
        using=using,
        ^^^^^^^^^^^^
    ...<2 lines>...
        update_fields=update_fields,
        ^^^^^^^^^^^^^^^^^^^^^^^^^^^^
    )
    ^
  File "/Library/Frameworks/Python.framework/Versions/3.13/lib/python3.13/site-packages/django/db/models/base.py", line 1012, in save_base
    post_save.send(
    ~~~~~~~~~~~~~~^
        sender=origin,
        ^^^^^^^^^^^^^^
    ...<4 lines>...
        using=using,
        ^^^^^^^^^^^^
    )
    ^
  File "/Library/Frameworks/Python.framework/Versions/3.13/lib/python3.13/site-packages/django/dispatch/dispatcher.py", line 189, in send
    response = receiver(signal=self, sender=sender, **named)
  File "/Users/danieloh/ssa_project/users/models.py", line 10, in create_user_profile
    Profile.objects.get_or_create(user=instance)  # Safely create the profile without duplicating
    ~~~~~~~~~~~~~~~~~~~~~~~~~~~~~^^^^^^^^^^^^^^^
  File "/Library/Frameworks/Python.framework/Versions/3.13/lib/python3.13/site-packages/django/db/models/manager.py", line 87, in manager_method
    return getattr(self.get_queryset(), name)(*args, **kwargs)
           ~~~~~~~~~~~~~~~~~~~~~~~~~~~~~~~~~~^^^^^^^^^^^^^^^^^
  File "/Library/Frameworks/Python.framework/Versions/3.13/lib/python3.13/site-packages/django/db/models/query.py", line 955, in get_or_create
    return self.create(**params), True
           ~~~~~~~~~~~^^^^^^^^^^
  File "/Library/Frameworks/Python.framework/Versions/3.13/lib/python3.13/site-packages/django/db/models/query.py", line 679, in create
    obj.save(force_insert=True, using=self.db)
    ~~~~~~~~^^^^^^^^^^^^^^^^^^^^^^^^^^^^^^^^^^
  File "/Users/danieloh/ssa_project/users/models.py", line 36, in save
    self.clean()
    ~~~~~~~~~~^^
  File "/Users/danieloh/ssa_project/users/models.py", line 33, in clean
    validate_unique_nickname(self.nickname, instance=self)
    ~~~~~~~~~~~~~~~~~~~~~~~~^^^^^^^^^^^^^^^^^^^^^^^^^^^^^^
  File "/Users/danieloh/ssa_project/users/models.py", line 21, in validate_unique_nickname
    raise ValidationError(f"Nickname '{nickname}' is already taken.")
django.core.exceptions.ValidationError: ["Nickname '' is already taken."]
"POST /users/register/ HTTP/1.1" 500 123618
Internal Server Error: /chipin/group/2/request/1/vote/approve/
Traceback (most recent call last):
  File "/Library/Frameworks/Python.framework/Versions/3.13/lib/python3.13/site-packages/django/core/handlers/exception.py", line 55, in inner
    response = get_response(request)
  File "/Library/Frameworks/Python.framework/Versions/3.13/lib/python3.13/site-packages/django/core/handlers/base.py", line 197, in _get_response
    response = wrapped_callback(request, *callback_args, **callback_kwargs)
  File "/Library/Frameworks/Python.framework/Versions/3.13/lib/python3.13/site-packages/django/contrib/auth/decorators.py", line 60, in _view_wrapper
    return view_func(request, *args, **kwargs)
  File "/Users/danieloh/ssa_project/chipin/views.py", line 242, in vote_on_join_request
    messages.success(request, f"{join_request.user.profile.nickname} has been approved to join the group!")
                                 ^^^^^^^^^^^^^^^^^^^^^^^^^
  File "/Library/Frameworks/Python.framework/Versions/3.13/lib/python3.13/site-packages/django/db/models/fields/related_descriptors.py", line 531, in __get__
    raise self.RelatedObjectDoesNotExist(
    ...<2 lines>...
    )
django.contrib.auth.models.User.profile.RelatedObjectDoesNotExist: User has no profile.
"GET /chipin/group/2/request/1/vote/approve/ HTTP/1.1" 500 71807
Internal Server Error: /users/register/
Traceback (most recent call last):
  File "/Library/Frameworks/Python.framework/Versions/3.13/lib/python3.13/site-packages/django/db/models/query.py", line 948, in get_or_create
    return self.get(**kwargs), False
           ~~~~~~~~^^^^^^^^^^
  File "/Library/Frameworks/Python.framework/Versions/3.13/lib/python3.13/site-packages/django/db/models/query.py", line 649, in get
    raise self.model.DoesNotExist(
        "%s matching query does not exist." % self.model._meta.object_name
    )
users.models.Profile.DoesNotExist: Profile matching query does not exist.

During handling of the above exception, another exception occurred:

Traceback (most recent call last):
  File "/Library/Frameworks/Python.framework/Versions/3.13/lib/python3.13/site-packages/django/core/handlers/exception.py", line 55, in inner
    response = get_response(request)
  File "/Library/Frameworks/Python.framework/Versions/3.13/lib/python3.13/site-packages/django/core/handlers/base.py", line 197, in _get_response
    response = wrapped_callback(request, *callback_args, **callback_kwargs)
  File "/Users/danieloh/ssa_project/users/views.py", line 17, in register
    form.save()
    ~~~~~~~~~^^
  File "/Users/danieloh/ssa_project/users/forms.py", line 22, in save
    user.save()
    ~~~~~~~~~^^
  File "/Library/Frameworks/Python.framework/Versions/3.13/lib/python3.13/site-packages/django/contrib/auth/base_user.py", line 62, in save
    super().save(*args, **kwargs)
    ~~~~~~~~~~~~^^^^^^^^^^^^^^^^^
  File "/Library/Frameworks/Python.framework/Versions/3.13/lib/python3.13/site-packages/django/db/models/base.py", line 891, in save
    self.save_base(
    ~~~~~~~~~~~~~~^
        using=using,
        ^^^^^^^^^^^^
    ...<2 lines>...
        update_fields=update_fields,
        ^^^^^^^^^^^^^^^^^^^^^^^^^^^^
    )
    ^
  File "/Library/Frameworks/Python.framework/Versions/3.13/lib/python3.13/site-packages/django/db/models/base.py", line 1012, in save_base
    post_save.send(
    ~~~~~~~~~~~~~~^
        sender=origin,
        ^^^^^^^^^^^^^^
    ...<4 lines>...
        using=using,
        ^^^^^^^^^^^^
    )
    ^
  File "/Library/Frameworks/Python.framework/Versions/3.13/lib/python3.13/site-packages/django/dispatch/dispatcher.py", line 189, in send
    response = receiver(signal=self, sender=sender, **named)
  File "/Users/danieloh/ssa_project/users/models.py", line 10, in create_user_profile
    Profile.objects.get_or_create(user=instance)  # Safely create the profile without duplicating
    ~~~~~~~~~~~~~~~~~~~~~~~~~~~~~^^^^^^^^^^^^^^^
  File "/Library/Frameworks/Python.framework/Versions/3.13/lib/python3.13/site-packages/django/db/models/manager.py", line 87, in manager_method
    return getattr(self.get_queryset(), name)(*args, **kwargs)
           ~~~~~~~~~~~~~~~~~~~~~~~~~~~~~~~~~~^^^^^^^^^^^^^^^^^
  File "/Library/Frameworks/Python.framework/Versions/3.13/lib/python3.13/site-packages/django/db/models/query.py", line 955, in get_or_create
    return self.create(**params), True
           ~~~~~~~~~~~^^^^^^^^^^
  File "/Library/Frameworks/Python.framework/Versions/3.13/lib/python3.13/site-packages/django/db/models/query.py", line 679, in create
    obj.save(force_insert=True, using=self.db)
    ~~~~~~~~^^^^^^^^^^^^^^^^^^^^^^^^^^^^^^^^^^
  File "/Users/danieloh/ssa_project/users/models.py", line 38, in save
    self.clean()
    ~~~~~~~~~~^^
  File "/Users/danieloh/ssa_project/users/models.py", line 35, in clean
    validate_unique_nickname(self.nickname, instance=self)
    ~~~~~~~~~~~~~~~~~~~~~~~~^^^^^^^^^^^^^^^^^^^^^^^^^^^^^^
  File "/Users/danieloh/ssa_project/users/models.py", line 21, in validate_unique_nickname
    raise ValidationError(f"Nickname '{nickname}' is already taken.")
django.core.exceptions.ValidationError: ["Nickname '' is already taken."]
"POST /users/register/ HTTP/1.1" 500 124023
Internal Server Error: /chipin/group/2/
Traceback (most recent call last):
  File "/Library/Frameworks/Python.framework/Versions/3.13/lib/python3.13/site-packages/django/core/handlers/exception.py", line 55, in inner
    response = get_response(request)
  File "/Library/Frameworks/Python.framework/Versions/3.13/lib/python3.13/site-packages/django/core/handlers/base.py", line 197, in _get_response
    response = wrapped_callback(request, *callback_args, **callback_kwargs)
  File "/Library/Frameworks/Python.framework/Versions/3.13/lib/python3.13/site-packages/django/contrib/auth/decorators.py", line 60, in _view_wrapper
    return view_func(request, *args, **kwargs)
  File "/Users/danieloh/ssa_project/chipin/views.py", line 167, in group_detail
    user_eligible = request.user.profile.max_spend >= event_share
                    ^^^^^^^^^^^^^^^^^^^^
  File "/Library/Frameworks/Python.framework/Versions/3.13/lib/python3.13/site-packages/django/utils/functional.py", line 253, in inner
    return func(_wrapped, *args)
  File "/Library/Frameworks/Python.framework/Versions/3.13/lib/python3.13/site-packages/django/db/models/fields/related_descriptors.py", line 531, in __get__
    raise self.RelatedObjectDoesNotExist(
    ...<2 lines>...
    )
django.contrib.auth.models.User.profile.RelatedObjectDoesNotExist: User has no profile.
"GET /chipin/group/2/ HTTP/1.1" 500 77112
Internal Server Error: /chipin/group/2/
Traceback (most recent call last):
  File "/Library/Frameworks/Python.framework/Versions/3.13/lib/python3.13/site-packages/django/core/handlers/exception.py", line 55, in inner
    response = get_response(request)
  File "/Library/Frameworks/Python.framework/Versions/3.13/lib/python3.13/site-packages/django/core/handlers/base.py", line 197, in _get_response
    response = wrapped_callback(request, *callback_args, **callback_kwargs)
  File "/Library/Frameworks/Python.framework/Versions/3.13/lib/python3.13/site-packages/django/contrib/auth/decorators.py", line 60, in _view_wrapper
    return view_func(request, *args, **kwargs)
  File "/Users/danieloh/ssa_project/chipin/views.py", line 167, in group_detail
    user_eligible = request.user.profile.max_spend >= event_share
                    ^^^^^^^^^^^^^^^^^^^^
  File "/Library/Frameworks/Python.framework/Versions/3.13/lib/python3.13/site-packages/django/utils/functional.py", line 253, in inner
    return func(_wrapped, *args)
  File "/Library/Frameworks/Python.framework/Versions/3.13/lib/python3.13/site-packages/django/db/models/fields/related_descriptors.py", line 531, in __get__
    raise self.RelatedObjectDoesNotExist(
    ...<2 lines>...
    )
django.contrib.auth.models.User.profile.RelatedObjectDoesNotExist: User has no profile.
"GET /chipin/group/2/ HTTP/1.1" 500 77155
Internal Server Error: /chipin/group/2/
Traceback (most recent call last):
  File "/Library/Frameworks/Python.framework/Versions/3.13/lib/python3.13/site-packages/django/core/handlers/exception.py", line 55, in inner
    response = get_response(request)
  File "/Library/Frameworks/Python.framework/Versions/3.13/lib/python3.13/site-packages/django/core/handlers/base.py", line 197, in _get_response
    response = wrapped_callback(request, *callback_args, **callback_kwargs)
  File "/Library/Frameworks/Python.framework/Versions/3.13/lib/python3.13/site-packages/django/contrib/auth/decorators.py", line 60, in _view_wrapper
    return view_func(request, *args, **kwargs)
  File "/Users/danieloh/ssa_project/chipin/views.py", line 167, in group_detail
    user_eligible = request.user.profile.max_spend >= event_share
                    ^^^^^^^^^^^^^^^^^^^^
  File "/Library/Frameworks/Python.framework/Versions/3.13/lib/python3.13/site-packages/django/utils/functional.py", line 253, in inner
    return func(_wrapped, *args)
  File "/Library/Frameworks/Python.framework/Versions/3.13/lib/python3.13/site-packages/django/db/models/fields/related_descriptors.py", line 531, in __get__
    raise self.RelatedObjectDoesNotExist(
    ...<2 lines>...
    )
django.contrib.auth.models.User.profile.RelatedObjectDoesNotExist: User has no profile.
"GET /chipin/group/2/ HTTP/1.1" 500 77155
Internal Server Error: /chipin/group/2/
Traceback (most recent call last):
  File "/Library/Frameworks/Python.framework/Versions/3.13/lib/python3.13/site-packages/django/core/handlers/exception.py", line 55, in inner
    response = get_response(request)
  File "/Library/Frameworks/Python.framework/Versions/3.13/lib/python3.13/site-packages/django/core/handlers/base.py", line 197, in _get_response
    response = wrapped_callback(request, *callback_args, **callback_kwargs)
  File "/Library/Frameworks/Python.framework/Versions/3.13/lib/python3.13/site-packages/django/contrib/auth/decorators.py", line 60, in _view_wrapper
    return view_func(request, *args, **kwargs)
  File "/Users/danieloh/ssa_project/chipin/views.py", line 167, in group_detail
    user_eligible = request.user.profile.max_spend >= event_share
                    ^^^^^^^^^^^^^^^^^^^^
  File "/Library/Frameworks/Python.framework/Versions/3.13/lib/python3.13/site-packages/django/utils/functional.py", line 253, in inner
    return func(_wrapped, *args)
  File "/Library/Frameworks/Python.framework/Versions/3.13/lib/python3.13/site-packages/django/db/models/fields/related_descriptors.py", line 531, in __get__
    raise self.RelatedObjectDoesNotExist(
    ...<2 lines>...
    )
django.contrib.auth.models.User.profile.RelatedObjectDoesNotExist: User has no profile.
"GET /chipin/group/2/ HTTP/1.1" 500 77178
Internal Server Error: /chipin/group/2/
Traceback (most recent call last):
  File "/Library/Frameworks/Python.framework/Versions/3.13/lib/python3.13/site-packages/django/core/handlers/exception.py", line 55, in inner
    response = get_response(request)
  File "/Library/Frameworks/Python.framework/Versions/3.13/lib/python3.13/site-packages/django/core/handlers/base.py", line 197, in _get_response
    response = wrapped_callback(request, *callback_args, **callback_kwargs)
  File "/Library/Frameworks/Python.framework/Versions/3.13/lib/python3.13/site-packages/django/contrib/auth/decorators.py", line 60, in _view_wrapper
    return view_func(request, *args, **kwargs)
  File "/Users/danieloh/ssa_project/chipin/views.py", line 167, in group_detail
    user_eligible = request.user.profile.max_spend >= event_share
                    ^^^^^^^^^^^^^^^^^^^^
  File "/Library/Frameworks/Python.framework/Versions/3.13/lib/python3.13/site-packages/django/utils/functional.py", line 253, in inner
    return func(_wrapped, *args)
  File "/Library/Frameworks/Python.framework/Versions/3.13/lib/python3.13/site-packages/django/db/models/fields/related_descriptors.py", line 531, in __get__
    raise self.RelatedObjectDoesNotExist(
    ...<2 lines>...
    )
django.contrib.auth.models.User.profile.RelatedObjectDoesNotExist: User has no profile.
"GET /chipin/group/2/ HTTP/1.1" 500 77041
Internal Server Error: /chipin/group/2/
Traceback (most recent call last):
  File "/Library/Frameworks/Python.framework/Versions/3.13/lib/python3.13/site-packages/django/core/handlers/exception.py", line 55, in inner
    response = get_response(request)
  File "/Library/Frameworks/Python.framework/Versions/3.13/lib/python3.13/site-packages/django/core/handlers/base.py", line 197, in _get_response
    response = wrapped_callback(request, *callback_args, **callback_kwargs)
  File "/Library/Frameworks/Python.framework/Versions/3.13/lib/python3.13/site-packages/django/contrib/auth/decorators.py", line 60, in _view_wrapper
    return view_func(request, *args, **kwargs)
  File "/Users/danieloh/ssa_project/chipin/views.py", line 167, in group_detail
    user_eligible = request.user.profile.max_spend >= event_share
                    ^^^^^^^^^^^^^^^^^^^^
  File "/Library/Frameworks/Python.framework/Versions/3.13/lib/python3.13/site-packages/django/utils/functional.py", line 253, in inner
    return func(_wrapped, *args)
  File "/Library/Frameworks/Python.framework/Versions/3.13/lib/python3.13/site-packages/django/db/models/fields/related_descriptors.py", line 531, in __get__
    raise self.RelatedObjectDoesNotExist(
    ...<2 lines>...
    )
django.contrib.auth.models.User.profile.RelatedObjectDoesNotExist: User has no profile.
"GET /chipin/group/2/ HTTP/1.1" 500 76743
Internal Server Error: /chipin/create_group/
Traceback (most recent call last):
  File "/Library/Frameworks/Python.framework/Versions/3.13/lib/python3.13/site-packages/django/core/handlers/exception.py", line 55, in inner
    response = get_response(request)
  File "/Library/Frameworks/Python.framework/Versions/3.13/lib/python3.13/site-packages/django/core/handlers/base.py", line 197, in _get_response
    response = wrapped_callback(request, *callback_args, **callback_kwargs)
  File "/Library/Frameworks/Python.framework/Versions/3.13/lib/python3.13/site-packages/django/contrib/auth/decorators.py", line 60, in _view_wrapper
    return view_func(request, *args, **kwargs)
  File "/Users/danieloh/ssa_project/chipin/views.py", line 133, in create_group
    return redirect('group_detail', group_id=group.id)
  File "/Library/Frameworks/Python.framework/Versions/3.13/lib/python3.13/site-packages/django/shortcuts.py", line 49, in redirect
    return redirect_class(resolve_url(to, *args, **kwargs))
                          ~~~~~~~~~~~^^^^^^^^^^^^^^^^^^^^^
  File "/Library/Frameworks/Python.framework/Versions/3.13/lib/python3.13/site-packages/django/shortcuts.py", line 180, in resolve_url
    return reverse(to, args=args, kwargs=kwargs)
  File "/Library/Frameworks/Python.framework/Versions/3.13/lib/python3.13/site-packages/django/urls/base.py", line 88, in reverse
    return resolver._reverse_with_prefix(view, prefix, *args, **kwargs)
           ~~~~~~~~~~~~~~~~~~~~~~~~~~~~~^^^^^^^^^^^^^^^^^^^^^^^^^^^^^^^
  File "/Library/Frameworks/Python.framework/Versions/3.13/lib/python3.13/site-packages/django/urls/resolvers.py", line 831, in _reverse_with_prefix
    raise NoReverseMatch(msg)
django.urls.exceptions.NoReverseMatch: Reverse for 'group_detail' not found. 'group_detail' is not a valid view function or pattern name.
"POST /chipin/create_group/ HTTP/1.1" 500 86090
Internal Server Error: /chipin/create_group/
Traceback (most recent call last):
  File "/Library/Frameworks/Python.framework/Versions/3.13/lib/python3.13/site-packages/django/core/handlers/exception.py", line 55, in inner
    response = get_response(request)
  File "/Library/Frameworks/Python.framework/Versions/3.13/lib/python3.13/site-packages/django/core/handlers/base.py", line 197, in _get_response
    response = wrapped_callback(request, *callback_args, **callback_kwargs)
  File "/Library/Frameworks/Python.framework/Versions/3.13/lib/python3.13/site-packages/django/contrib/auth/decorators.py", line 60, in _view_wrapper
    return view_func(request, *args, **kwargs)
  File "/Users/danieloh/ssa_project/chipin/views.py", line 133, in create_group
    return redirect('group_detail', group_id=group.id)
  File "/Library/Frameworks/Python.framework/Versions/3.13/lib/python3.13/site-packages/django/shortcuts.py", line 49, in redirect
    return redirect_class(resolve_url(to, *args, **kwargs))
                          ~~~~~~~~~~~^^^^^^^^^^^^^^^^^^^^^
  File "/Library/Frameworks/Python.framework/Versions/3.13/lib/python3.13/site-packages/django/shortcuts.py", line 180, in resolve_url
    return reverse(to, args=args, kwargs=kwargs)
  File "/Library/Frameworks/Python.framework/Versions/3.13/lib/python3.13/site-packages/django/urls/base.py", line 88, in reverse
    return resolver._reverse_with_prefix(view, prefix, *args, **kwargs)
           ~~~~~~~~~~~~~~~~~~~~~~~~~~~~~^^^^^^^^^^^^^^^^^^^^^^^^^^^^^^^
  File "/Library/Frameworks/Python.framework/Versions/3.13/lib/python3.13/site-packages/django/urls/resolvers.py", line 831, in _reverse_with_prefix
    raise NoReverseMatch(msg)
django.urls.exceptions.NoReverseMatch: Reverse for 'group_detail' not found. 'group_detail' is not a valid view function or pattern name.
"POST /chipin/create_group/ HTTP/1.1" 500 86109
Internal Server Error: /chipin/group/5/
Traceback (most recent call last):
  File "/Library/Frameworks/Python.framework/Versions/3.13/lib/python3.13/site-packages/django/core/handlers/exception.py", line 55, in inner
    response = get_response(request)
  File "/Library/Frameworks/Python.framework/Versions/3.13/lib/python3.13/site-packages/django/core/handlers/base.py", line 197, in _get_response
    response = wrapped_callback(request, *callback_args, **callback_kwargs)
  File "/Library/Frameworks/Python.framework/Versions/3.13/lib/python3.13/site-packages/django/contrib/auth/decorators.py", line 60, in _view_wrapper
    return view_func(request, *args, **kwargs)
  File "/Users/danieloh/ssa_project/chipin/views.py", line 73, in group_detail
    user_eligible = request.user.profile.max_spend >= event_share
                    ^^^^^^^^^^^^^^^^^^^^
  File "/Library/Frameworks/Python.framework/Versions/3.13/lib/python3.13/site-packages/django/utils/functional.py", line 253, in inner
    return func(_wrapped, *args)
  File "/Library/Frameworks/Python.framework/Versions/3.13/lib/python3.13/site-packages/django/db/models/fields/related_descriptors.py", line 531, in __get__
    raise self.RelatedObjectDoesNotExist(
    ...<2 lines>...
    )
django.contrib.auth.models.User.profile.RelatedObjectDoesNotExist: User has no profile.
"GET /chipin/group/5/ HTTP/1.1" 500 77031
Internal Server Error: /chipin/group/6/
Traceback (most recent call last):
  File "/Library/Frameworks/Python.framework/Versions/3.13/lib/python3.13/site-packages/django/core/handlers/exception.py", line 55, in inner
    response = get_response(request)
  File "/Library/Frameworks/Python.framework/Versions/3.13/lib/python3.13/site-packages/django/core/handlers/base.py", line 197, in _get_response
    response = wrapped_callback(request, *callback_args, **callback_kwargs)
  File "/Library/Frameworks/Python.framework/Versions/3.13/lib/python3.13/site-packages/django/contrib/auth/decorators.py", line 60, in _view_wrapper
    return view_func(request, *args, **kwargs)
  File "/Users/danieloh/ssa_project/chipin/views.py", line 73, in group_detail
    user_eligible = request.user.profile.max_spend >= event_share
                    ^^^^^^^^^^^^^^^^^^^^
  File "/Library/Frameworks/Python.framework/Versions/3.13/lib/python3.13/site-packages/django/utils/functional.py", line 253, in inner
    return func(_wrapped, *args)
  File "/Library/Frameworks/Python.framework/Versions/3.13/lib/python3.13/site-packages/django/db/models/fields/related_descriptors.py", line 531, in __get__
    raise self.RelatedObjectDoesNotExist(
    ...<2 lines>...
    )
django.contrib.auth.models.User.profile.RelatedObjectDoesNotExist: User has no profile.
"GET /chipin/group/6/ HTTP/1.1" 500 77038
Internal Server Error: /chipin/group/6/event/5/join/
Traceback (most recent call last):
  File "/Library/Frameworks/Python.framework/Versions/3.13/lib/python3.13/site-packages/django/core/handlers/exception.py", line 55, in inner
    response = get_response(request)
  File "/Library/Frameworks/Python.framework/Versions/3.13/lib/python3.13/site-packages/django/core/handlers/base.py", line 197, in _get_response
    response = wrapped_callback(request, *callback_args, **callback_kwargs)
  File "/Library/Frameworks/Python.framework/Versions/3.13/lib/python3.13/site-packages/django/contrib/auth/decorators.py", line 60, in _view_wrapper
    return view_func(request, *args, **kwargs)
  File "/Users/danieloh/ssa_project/chipin/views.py", line 128, in join_event
    event.check_status()
    ~~~~~~~~~~~~~~~~~~^^
  File "/Users/danieloh/ssa_project/chipin/models.py", line 48, in check_status
    if member.profile.max_spend < share:
       ^^^^^^^^^^^^^^
  File "/Library/Frameworks/Python.framework/Versions/3.13/lib/python3.13/site-packages/django/db/models/fields/related_descriptors.py", line 531, in __get__
    raise self.RelatedObjectDoesNotExist(
    ...<2 lines>...
    )
django.contrib.auth.models.User.profile.RelatedObjectDoesNotExist: User has no profile.
"GET /chipin/group/6/event/5/join/ HTTP/1.1" 500 75297
Internal Server Error: /chipin/group/6/
Traceback (most recent call last):
  File "/Library/Frameworks/Python.framework/Versions/3.13/lib/python3.13/site-packages/django/core/handlers/exception.py", line 55, in inner
    response = get_response(request)
  File "/Library/Frameworks/Python.framework/Versions/3.13/lib/python3.13/site-packages/django/core/handlers/base.py", line 197, in _get_response
    response = wrapped_callback(request, *callback_args, **callback_kwargs)
  File "/Library/Frameworks/Python.framework/Versions/3.13/lib/python3.13/site-packages/django/contrib/auth/decorators.py", line 60, in _view_wrapper
    return view_func(request, *args, **kwargs)
  File "/Users/danieloh/ssa_project/chipin/views.py", line 73, in group_detail
    user_eligible = request.user.profile.max_spend >= event_share
                    ^^^^^^^^^^^^^^^^^^^^
  File "/Library/Frameworks/Python.framework/Versions/3.13/lib/python3.13/site-packages/django/utils/functional.py", line 253, in inner
    return func(_wrapped, *args)
  File "/Library/Frameworks/Python.framework/Versions/3.13/lib/python3.13/site-packages/django/db/models/fields/related_descriptors.py", line 531, in __get__
    raise self.RelatedObjectDoesNotExist(
    ...<2 lines>...
    )
django.contrib.auth.models.User.profile.RelatedObjectDoesNotExist: User has no profile.
"GET /chipin/group/6/ HTTP/1.1" 500 76598
Internal Server Error: /chipin/group/6/
Traceback (most recent call last):
  File "/Library/Frameworks/Python.framework/Versions/3.13/lib/python3.13/site-packages/django/core/handlers/exception.py", line 55, in inner
    response = get_response(request)
  File "/Library/Frameworks/Python.framework/Versions/3.13/lib/python3.13/site-packages/django/core/handlers/base.py", line 197, in _get_response
    response = wrapped_callback(request, *callback_args, **callback_kwargs)
  File "/Library/Frameworks/Python.framework/Versions/3.13/lib/python3.13/site-packages/django/contrib/auth/decorators.py", line 60, in _view_wrapper
    return view_func(request, *args, **kwargs)
  File "/Users/danieloh/ssa_project/chipin/views.py", line 73, in group_detail
    user_eligible = request.user.profile.max_spend >= event_share
                    ^^^^^^^^^^^^^^^^^^^^
  File "/Library/Frameworks/Python.framework/Versions/3.13/lib/python3.13/site-packages/django/utils/functional.py", line 253, in inner
    return func(_wrapped, *args)
  File "/Library/Frameworks/Python.framework/Versions/3.13/lib/python3.13/site-packages/django/db/models/fields/related_descriptors.py", line 531, in __get__
    raise self.RelatedObjectDoesNotExist(
    ...<2 lines>...
    )
django.contrib.auth.models.User.profile.RelatedObjectDoesNotExist: User has no profile.
"GET /chipin/group/6/ HTTP/1.1" 500 76735
Internal Server Error: /users/login
Traceback (most recent call last):
  File "/Library/Frameworks/Python.framework/Versions/3.13/lib/python3.13/site-packages/django/core/handlers/exception.py", line 55, in inner
    response = get_response(request)
  File "/Library/Frameworks/Python.framework/Versions/3.13/lib/python3.13/site-packages/django/core/handlers/base.py", line 197, in _get_response
    response = wrapped_callback(request, *callback_args, **callback_kwargs)
  File "/Users/danieloh/ssa_project/users/views.py", line 67, in login_view
    login(request, user)
    ~~~~~^^^^^^^^^^^^^^^
  File "/Library/Frameworks/Python.framework/Versions/3.13/lib/python3.13/site-packages/django/contrib/auth/__init__.py", line 152, in login
    user_logged_in.send(sender=user.__class__, request=request, user=user)
    ~~~~~~~~~~~~~~~~~~~^^^^^^^^^^^^^^^^^^^^^^^^^^^^^^^^^^^^^^^^^^^^^^^^^^^
  File "/Library/Frameworks/Python.framework/Versions/3.13/lib/python3.13/site-packages/django/dispatch/dispatcher.py", line 189, in send
    response = receiver(signal=self, sender=sender, **named)
  File "/Library/Frameworks/Python.framework/Versions/3.13/lib/python3.13/site-packages/django/contrib/auth/models.py", line 24, in update_last_login
    user.save(update_fields=["last_login"])
    ~~~~~~~~~^^^^^^^^^^^^^^^^^^^^^^^^^^^^^^
  File "/Library/Frameworks/Python.framework/Versions/3.13/lib/python3.13/site-packages/django/contrib/auth/base_user.py", line 62, in save
    super().save(*args, **kwargs)
    ~~~~~~~~~~~~^^^^^^^^^^^^^^^^^
  File "/Library/Frameworks/Python.framework/Versions/3.13/lib/python3.13/site-packages/django/db/models/base.py", line 891, in save
    self.save_base(
    ~~~~~~~~~~~~~~^
        using=using,
        ^^^^^^^^^^^^
    ...<2 lines>...
        update_fields=update_fields,
        ^^^^^^^^^^^^^^^^^^^^^^^^^^^^
    )
    ^
  File "/Library/Frameworks/Python.framework/Versions/3.13/lib/python3.13/site-packages/django/db/models/base.py", line 1012, in save_base
    post_save.send(
    ~~~~~~~~~~~~~~^
        sender=origin,
        ^^^^^^^^^^^^^^
    ...<4 lines>...
        using=using,
        ^^^^^^^^^^^^
    )
    ^
  File "/Library/Frameworks/Python.framework/Versions/3.13/lib/python3.13/site-packages/django/dispatch/dispatcher.py", line 189, in send
    response = receiver(signal=self, sender=sender, **named)
  File "/Users/danieloh/ssa_project/users/models.py", line 16, in save_user_profile
    instance.profile.save()
    ^^^^^^^^^^^^^^^^
  File "/Library/Frameworks/Python.framework/Versions/3.13/lib/python3.13/site-packages/django/db/models/fields/related_descriptors.py", line 531, in __get__
    raise self.RelatedObjectDoesNotExist(
    ...<2 lines>...
    )
django.contrib.auth.models.User.profile.RelatedObjectDoesNotExist: User has no profile.
"POST /users/login HTTP/1.1" 500 107684
Internal Server Error: /users/login
Traceback (most recent call last):
  File "/Library/Frameworks/Python.framework/Versions/3.13/lib/python3.13/site-packages/django/core/handlers/exception.py", line 55, in inner
    response = get_response(request)
  File "/Library/Frameworks/Python.framework/Versions/3.13/lib/python3.13/site-packages/django/core/handlers/base.py", line 197, in _get_response
    response = wrapped_callback(request, *callback_args, **callback_kwargs)
  File "/Users/danieloh/ssa_project/users/views.py", line 67, in login_view
    login(request, user)
    ~~~~~^^^^^^^^^^^^^^^
  File "/Library/Frameworks/Python.framework/Versions/3.13/lib/python3.13/site-packages/django/contrib/auth/__init__.py", line 152, in login
    user_logged_in.send(sender=user.__class__, request=request, user=user)
    ~~~~~~~~~~~~~~~~~~~^^^^^^^^^^^^^^^^^^^^^^^^^^^^^^^^^^^^^^^^^^^^^^^^^^^
  File "/Library/Frameworks/Python.framework/Versions/3.13/lib/python3.13/site-packages/django/dispatch/dispatcher.py", line 189, in send
    response = receiver(signal=self, sender=sender, **named)
  File "/Library/Frameworks/Python.framework/Versions/3.13/lib/python3.13/site-packages/django/contrib/auth/models.py", line 24, in update_last_login
    user.save(update_fields=["last_login"])
    ~~~~~~~~~^^^^^^^^^^^^^^^^^^^^^^^^^^^^^^
  File "/Library/Frameworks/Python.framework/Versions/3.13/lib/python3.13/site-packages/django/contrib/auth/base_user.py", line 62, in save
    super().save(*args, **kwargs)
    ~~~~~~~~~~~~^^^^^^^^^^^^^^^^^
  File "/Library/Frameworks/Python.framework/Versions/3.13/lib/python3.13/site-packages/django/db/models/base.py", line 891, in save
    self.save_base(
    ~~~~~~~~~~~~~~^
        using=using,
        ^^^^^^^^^^^^
    ...<2 lines>...
        update_fields=update_fields,
        ^^^^^^^^^^^^^^^^^^^^^^^^^^^^
    )
    ^
  File "/Library/Frameworks/Python.framework/Versions/3.13/lib/python3.13/site-packages/django/db/models/base.py", line 1012, in save_base
    post_save.send(
    ~~~~~~~~~~~~~~^
        sender=origin,
        ^^^^^^^^^^^^^^
    ...<4 lines>...
        using=using,
        ^^^^^^^^^^^^
    )
    ^
  File "/Library/Frameworks/Python.framework/Versions/3.13/lib/python3.13/site-packages/django/dispatch/dispatcher.py", line 189, in send
    response = receiver(signal=self, sender=sender, **named)
  File "/Users/danieloh/ssa_project/users/models.py", line 15, in save_user_profile
    instance.profile.save()
    ^^^^^^^^^^^^^^^^
  File "/Library/Frameworks/Python.framework/Versions/3.13/lib/python3.13/site-packages/django/db/models/fields/related_descriptors.py", line 531, in __get__
    raise self.RelatedObjectDoesNotExist(
    ...<2 lines>...
    )
django.contrib.auth.models.User.profile.RelatedObjectDoesNotExist: User has no profile.
"POST /users/login HTTP/1.1" 500 107663
Internal Server Error: /users/register/
Traceback (most recent call last):
  File "/Library/Frameworks/Python.framework/Versions/3.13/lib/python3.13/site-packages/django/db/models/query.py", line 948, in get_or_create
    return self.get(**kwargs), False
           ~~~~~~~~^^^^^^^^^^
  File "/Library/Frameworks/Python.framework/Versions/3.13/lib/python3.13/site-packages/django/db/models/query.py", line 649, in get
    raise self.model.DoesNotExist(
        "%s matching query does not exist." % self.model._meta.object_name
    )
users.models.Profile.DoesNotExist: Profile matching query does not exist.

During handling of the above exception, another exception occurred:

Traceback (most recent call last):
  File "/Library/Frameworks/Python.framework/Versions/3.13/lib/python3.13/site-packages/django/core/handlers/exception.py", line 55, in inner
    response = get_response(request)
  File "/Library/Frameworks/Python.framework/Versions/3.13/lib/python3.13/site-packages/django/core/handlers/base.py", line 197, in _get_response
    response = wrapped_callback(request, *callback_args, **callback_kwargs)
  File "/Users/danieloh/ssa_project/users/views.py", line 13, in register
    form.save()
    ~~~~~~~~~^^
  File "/Users/danieloh/ssa_project/users/forms.py", line 22, in save
    user.save()
    ~~~~~~~~~^^
  File "/Library/Frameworks/Python.framework/Versions/3.13/lib/python3.13/site-packages/django/contrib/auth/base_user.py", line 62, in save
    super().save(*args, **kwargs)
    ~~~~~~~~~~~~^^^^^^^^^^^^^^^^^
  File "/Library/Frameworks/Python.framework/Versions/3.13/lib/python3.13/site-packages/django/db/models/base.py", line 891, in save
    self.save_base(
    ~~~~~~~~~~~~~~^
        using=using,
        ^^^^^^^^^^^^
    ...<2 lines>...
        update_fields=update_fields,
        ^^^^^^^^^^^^^^^^^^^^^^^^^^^^
    )
    ^
  File "/Library/Frameworks/Python.framework/Versions/3.13/lib/python3.13/site-packages/django/db/models/base.py", line 1012, in save_base
    post_save.send(
    ~~~~~~~~~~~~~~^
        sender=origin,
        ^^^^^^^^^^^^^^
    ...<4 lines>...
        using=using,
        ^^^^^^^^^^^^
    )
    ^
  File "/Library/Frameworks/Python.framework/Versions/3.13/lib/python3.13/site-packages/django/dispatch/dispatcher.py", line 189, in send
    response = receiver(signal=self, sender=sender, **named)
  File "/Users/danieloh/ssa_project/users/models.py", line 10, in create_user_profile
    Profile.objects.get_or_create(user=instance)  # Safely create the profile without duplicating
    ~~~~~~~~~~~~~~~~~~~~~~~~~~~~~^^^^^^^^^^^^^^^
  File "/Library/Frameworks/Python.framework/Versions/3.13/lib/python3.13/site-packages/django/db/models/manager.py", line 87, in manager_method
    return getattr(self.get_queryset(), name)(*args, **kwargs)
           ~~~~~~~~~~~~~~~~~~~~~~~~~~~~~~~~~~^^^^^^^^^^^^^^^^^
  File "/Library/Frameworks/Python.framework/Versions/3.13/lib/python3.13/site-packages/django/db/models/query.py", line 955, in get_or_create
    return self.create(**params), True
           ~~~~~~~~~~~^^^^^^^^^^
  File "/Library/Frameworks/Python.framework/Versions/3.13/lib/python3.13/site-packages/django/db/models/query.py", line 679, in create
    obj.save(force_insert=True, using=self.db)
    ~~~~~~~~^^^^^^^^^^^^^^^^^^^^^^^^^^^^^^^^^^
  File "/Users/danieloh/ssa_project/users/models.py", line 38, in save
    self.clean()
    ~~~~~~~~~~^^
  File "/Users/danieloh/ssa_project/users/models.py", line 35, in clean
    validate_unique_nickname(self.nickname, instance=self)
    ~~~~~~~~~~~~~~~~~~~~~~~~^^^^^^^^^^^^^^^^^^^^^^^^^^^^^^
  File "/Users/danieloh/ssa_project/users/models.py", line 21, in validate_unique_nickname
    raise ValidationError(f"Nickname '{nickname}' is already taken.")
django.core.exceptions.ValidationError: ["Nickname '' is already taken."]
"POST /users/register/ HTTP/1.1" 500 123918
Internal Server Error: /users/register/
Traceback (most recent call last):
  File "/Library/Frameworks/Python.framework/Versions/3.13/lib/python3.13/site-packages/django/db/models/query.py", line 948, in get_or_create
    return self.get(**kwargs), False
           ~~~~~~~~^^^^^^^^^^
  File "/Library/Frameworks/Python.framework/Versions/3.13/lib/python3.13/site-packages/django/db/models/query.py", line 649, in get
    raise self.model.DoesNotExist(
        "%s matching query does not exist." % self.model._meta.object_name
    )
users.models.Profile.DoesNotExist: Profile matching query does not exist.

During handling of the above exception, another exception occurred:

Traceback (most recent call last):
  File "/Library/Frameworks/Python.framework/Versions/3.13/lib/python3.13/site-packages/django/core/handlers/exception.py", line 55, in inner
    response = get_response(request)
  File "/Library/Frameworks/Python.framework/Versions/3.13/lib/python3.13/site-packages/django/core/handlers/base.py", line 197, in _get_response
    response = wrapped_callback(request, *callback_args, **callback_kwargs)
  File "/Users/danieloh/ssa_project/users/views.py", line 13, in register
    form.save()
    ~~~~~~~~~^^
  File "/Users/danieloh/ssa_project/users/forms.py", line 22, in save
    user.save()
    ~~~~~~~~~^^
  File "/Library/Frameworks/Python.framework/Versions/3.13/lib/python3.13/site-packages/django/contrib/auth/base_user.py", line 62, in save
    super().save(*args, **kwargs)
    ~~~~~~~~~~~~^^^^^^^^^^^^^^^^^
  File "/Library/Frameworks/Python.framework/Versions/3.13/lib/python3.13/site-packages/django/db/models/base.py", line 891, in save
    self.save_base(
    ~~~~~~~~~~~~~~^
        using=using,
        ^^^^^^^^^^^^
    ...<2 lines>...
        update_fields=update_fields,
        ^^^^^^^^^^^^^^^^^^^^^^^^^^^^
    )
    ^
  File "/Library/Frameworks/Python.framework/Versions/3.13/lib/python3.13/site-packages/django/db/models/base.py", line 1012, in save_base
    post_save.send(
    ~~~~~~~~~~~~~~^
        sender=origin,
        ^^^^^^^^^^^^^^
    ...<4 lines>...
        using=using,
        ^^^^^^^^^^^^
    )
    ^
  File "/Library/Frameworks/Python.framework/Versions/3.13/lib/python3.13/site-packages/django/dispatch/dispatcher.py", line 189, in send
    response = receiver(signal=self, sender=sender, **named)
  File "/Users/danieloh/ssa_project/users/models.py", line 10, in create_user_profile
    Profile.objects.get_or_create(user=instance)  # Safely create the profile without duplicating
    ~~~~~~~~~~~~~~~~~~~~~~~~~~~~~^^^^^^^^^^^^^^^
  File "/Library/Frameworks/Python.framework/Versions/3.13/lib/python3.13/site-packages/django/db/models/manager.py", line 87, in manager_method
    return getattr(self.get_queryset(), name)(*args, **kwargs)
           ~~~~~~~~~~~~~~~~~~~~~~~~~~~~~~~~~~^^^^^^^^^^^^^^^^^
  File "/Library/Frameworks/Python.framework/Versions/3.13/lib/python3.13/site-packages/django/db/models/query.py", line 955, in get_or_create
    return self.create(**params), True
           ~~~~~~~~~~~^^^^^^^^^^
  File "/Library/Frameworks/Python.framework/Versions/3.13/lib/python3.13/site-packages/django/db/models/query.py", line 679, in create
    obj.save(force_insert=True, using=self.db)
    ~~~~~~~~^^^^^^^^^^^^^^^^^^^^^^^^^^^^^^^^^^
  File "/Users/danieloh/ssa_project/users/models.py", line 38, in save
    self.clean()
    ~~~~~~~~~~^^
  File "/Users/danieloh/ssa_project/users/models.py", line 35, in clean
    validate_unique_nickname(self.nickname, instance=self)
    ~~~~~~~~~~~~~~~~~~~~~~~~^^^^^^^^^^^^^^^^^^^^^^^^^^^^^^
  File "/Users/danieloh/ssa_project/users/models.py", line 21, in validate_unique_nickname
    raise ValidationError(f"Nickname '{nickname}' is already taken.")
django.core.exceptions.ValidationError: ["Nickname '' is already taken."]
"POST /users/register/ HTTP/1.1" 500 123767
Internal Server Error: /chipin/group/6/
Traceback (most recent call last):
  File "/Library/Frameworks/Python.framework/Versions/3.13/lib/python3.13/site-packages/django/core/handlers/exception.py", line 55, in inner
    response = get_response(request)
  File "/Library/Frameworks/Python.framework/Versions/3.13/lib/python3.13/site-packages/django/core/handlers/base.py", line 197, in _get_response
    response = wrapped_callback(request, *callback_args, **callback_kwargs)
  File "/Library/Frameworks/Python.framework/Versions/3.13/lib/python3.13/site-packages/django/contrib/auth/decorators.py", line 60, in _view_wrapper
    return view_func(request, *args, **kwargs)
  File "/Users/danieloh/ssa_project/chipin/views.py", line 234, in group_detail
    user_eligible = request.user.profile.max_spend >= event_share
                    ^^^^^^^^^^^^^^^^^^^^
  File "/Library/Frameworks/Python.framework/Versions/3.13/lib/python3.13/site-packages/django/utils/functional.py", line 253, in inner
    return func(_wrapped, *args)
  File "/Library/Frameworks/Python.framework/Versions/3.13/lib/python3.13/site-packages/django/db/models/fields/related_descriptors.py", line 531, in __get__
    raise self.RelatedObjectDoesNotExist(
    ...<2 lines>...
    )
django.contrib.auth.models.User.profile.RelatedObjectDoesNotExist: User has no profile.
"GET /chipin/group/6/ HTTP/1.1" 500 76604
Internal Server Error: /chipin/group/6/
Traceback (most recent call last):
  File "/Library/Frameworks/Python.framework/Versions/3.13/lib/python3.13/site-packages/django/core/handlers/exception.py", line 55, in inner
    response = get_response(request)
  File "/Library/Frameworks/Python.framework/Versions/3.13/lib/python3.13/site-packages/django/core/handlers/base.py", line 197, in _get_response
    response = wrapped_callback(request, *callback_args, **callback_kwargs)
  File "/Library/Frameworks/Python.framework/Versions/3.13/lib/python3.13/site-packages/django/contrib/auth/decorators.py", line 60, in _view_wrapper
    return view_func(request, *args, **kwargs)
  File "/Users/danieloh/ssa_project/chipin/views.py", line 234, in group_detail
    user_eligible = request.user.profile.max_spend >= event_share
                    ^^^^^^^^^^^^^^^^^^^^
  File "/Library/Frameworks/Python.framework/Versions/3.13/lib/python3.13/site-packages/django/utils/functional.py", line 253, in inner
    return func(_wrapped, *args)
  File "/Library/Frameworks/Python.framework/Versions/3.13/lib/python3.13/site-packages/django/db/models/fields/related_descriptors.py", line 531, in __get__
    raise self.RelatedObjectDoesNotExist(
    ...<2 lines>...
    )
django.contrib.auth.models.User.profile.RelatedObjectDoesNotExist: User has no profile.
"GET /chipin/group/6/ HTTP/1.1" 500 76604
Internal Server Error: /chipin/group/6/
Traceback (most recent call last):
  File "/Library/Frameworks/Python.framework/Versions/3.13/lib/python3.13/site-packages/django/core/handlers/exception.py", line 55, in inner
    response = get_response(request)
  File "/Library/Frameworks/Python.framework/Versions/3.13/lib/python3.13/site-packages/django/core/handlers/base.py", line 197, in _get_response
    response = wrapped_callback(request, *callback_args, **callback_kwargs)
  File "/Library/Frameworks/Python.framework/Versions/3.13/lib/python3.13/site-packages/django/contrib/auth/decorators.py", line 60, in _view_wrapper
    return view_func(request, *args, **kwargs)
  File "/Users/danieloh/ssa_project/chipin/views.py", line 234, in group_detail
    user_eligible = request.user.profile.max_spend >= event_share
                    ^^^^^^^^^^^^^^^^^^^^
  File "/Library/Frameworks/Python.framework/Versions/3.13/lib/python3.13/site-packages/django/utils/functional.py", line 253, in inner
    return func(_wrapped, *args)
  File "/Library/Frameworks/Python.framework/Versions/3.13/lib/python3.13/site-packages/django/db/models/fields/related_descriptors.py", line 531, in __get__
    raise self.RelatedObjectDoesNotExist(
    ...<2 lines>...
    )
django.contrib.auth.models.User.profile.RelatedObjectDoesNotExist: User has no profile.
"GET /chipin/group/6/ HTTP/1.1" 500 76604
Internal Server Error: /chipin/group/6/
Traceback (most recent call last):
  File "/Library/Frameworks/Python.framework/Versions/3.13/lib/python3.13/site-packages/django/core/handlers/exception.py", line 55, in inner
    response = get_response(request)
  File "/Library/Frameworks/Python.framework/Versions/3.13/lib/python3.13/site-packages/django/core/handlers/base.py", line 197, in _get_response
    response = wrapped_callback(request, *callback_args, **callback_kwargs)
  File "/Library/Frameworks/Python.framework/Versions/3.13/lib/python3.13/site-packages/django/contrib/auth/decorators.py", line 60, in _view_wrapper
    return view_func(request, *args, **kwargs)
  File "/Users/danieloh/ssa_project/chipin/views.py", line 237, in group_detail
    user_eligible = request.user.profile.max_spend >= event_share
                    ^^^^^^^^^^^^^^^^^^^^
  File "/Library/Frameworks/Python.framework/Versions/3.13/lib/python3.13/site-packages/django/utils/functional.py", line 253, in inner
    return func(_wrapped, *args)
  File "/Library/Frameworks/Python.framework/Versions/3.13/lib/python3.13/site-packages/django/db/models/fields/related_descriptors.py", line 531, in __get__
    raise self.RelatedObjectDoesNotExist(
    ...<2 lines>...
    )
django.contrib.auth.models.User.profile.RelatedObjectDoesNotExist: User has no profile.
"GET /chipin/group/6/ HTTP/1.1" 500 76604
Internal Server Error: /chipin/group/6/
Traceback (most recent call last):
  File "/Library/Frameworks/Python.framework/Versions/3.13/lib/python3.13/site-packages/django/core/handlers/exception.py", line 55, in inner
    response = get_response(request)
  File "/Library/Frameworks/Python.framework/Versions/3.13/lib/python3.13/site-packages/django/core/handlers/base.py", line 197, in _get_response
    response = wrapped_callback(request, *callback_args, **callback_kwargs)
  File "/Library/Frameworks/Python.framework/Versions/3.13/lib/python3.13/site-packages/django/contrib/auth/decorators.py", line 60, in _view_wrapper
    return view_func(request, *args, **kwargs)
  File "/Users/danieloh/ssa_project/chipin/views.py", line 237, in group_detail
    user_eligible = request.user.profile.max_spend >= event_share
                    ^^^^^^^^^^^^^^^^^^^^
  File "/Library/Frameworks/Python.framework/Versions/3.13/lib/python3.13/site-packages/django/utils/functional.py", line 253, in inner
    return func(_wrapped, *args)
  File "/Library/Frameworks/Python.framework/Versions/3.13/lib/python3.13/site-packages/django/db/models/fields/related_descriptors.py", line 531, in __get__
    raise self.RelatedObjectDoesNotExist(
    ...<2 lines>...
    )
django.contrib.auth.models.User.profile.RelatedObjectDoesNotExist: User has no profile.
"GET /chipin/group/6/ HTTP/1.1" 500 76604
Internal Server Error: /chipin/group/7/
Traceback (most recent call last):
  File "/Library/Frameworks/Python.framework/Versions/3.13/lib/python3.13/site-packages/django/core/handlers/exception.py", line 55, in inner
    response = get_response(request)
  File "/Library/Frameworks/Python.framework/Versions/3.13/lib/python3.13/site-packages/django/core/handlers/base.py", line 197, in _get_response
    response = wrapped_callback(request, *callback_args, **callback_kwargs)
  File "/Library/Frameworks/Python.framework/Versions/3.13/lib/python3.13/site-packages/django/contrib/auth/decorators.py", line 60, in _view_wrapper
    return view_func(request, *args, **kwargs)
  File "/Users/danieloh/ssa_project/chipin/views.py", line 237, in group_detail
    user_eligible = request.user.profile.max_spend >= event_share
                    ^^^^^^^^^^^^^^^^^^^^
  File "/Library/Frameworks/Python.framework/Versions/3.13/lib/python3.13/site-packages/django/utils/functional.py", line 253, in inner
    return func(_wrapped, *args)
  File "/Library/Frameworks/Python.framework/Versions/3.13/lib/python3.13/site-packages/django/db/models/fields/related_descriptors.py", line 531, in __get__
    raise self.RelatedObjectDoesNotExist(
    ...<2 lines>...
    )
django.contrib.auth.models.User.profile.RelatedObjectDoesNotExist: User has no profile.
"GET /chipin/group/7/ HTTP/1.1" 500 77038
Internal Server Error: /chipin/group/7/
Traceback (most recent call last):
  File "/Library/Frameworks/Python.framework/Versions/3.13/lib/python3.13/site-packages/django/core/handlers/exception.py", line 55, in inner
    response = get_response(request)
  File "/Library/Frameworks/Python.framework/Versions/3.13/lib/python3.13/site-packages/django/core/handlers/base.py", line 197, in _get_response
    response = wrapped_callback(request, *callback_args, **callback_kwargs)
  File "/Library/Frameworks/Python.framework/Versions/3.13/lib/python3.13/site-packages/django/contrib/auth/decorators.py", line 60, in _view_wrapper
    return view_func(request, *args, **kwargs)
  File "/Users/danieloh/ssa_project/chipin/views.py", line 237, in group_detail
    user_eligible = request.user.profile.max_spend >= event_share
                    ^^^^^^^^^^^^^^^^^^^^
  File "/Library/Frameworks/Python.framework/Versions/3.13/lib/python3.13/site-packages/django/utils/functional.py", line 253, in inner
    return func(_wrapped, *args)
  File "/Library/Frameworks/Python.framework/Versions/3.13/lib/python3.13/site-packages/django/db/models/fields/related_descriptors.py", line 531, in __get__
    raise self.RelatedObjectDoesNotExist(
    ...<2 lines>...
    )
django.contrib.auth.models.User.profile.RelatedObjectDoesNotExist: User has no profile.
"GET /chipin/group/7/ HTTP/1.1" 500 77071
Internal Server Error: /chipin/group/7/
Traceback (most recent call last):
  File "/Library/Frameworks/Python.framework/Versions/3.13/lib/python3.13/site-packages/django/core/handlers/exception.py", line 55, in inner
    response = get_response(request)
  File "/Library/Frameworks/Python.framework/Versions/3.13/lib/python3.13/site-packages/django/core/handlers/base.py", line 197, in _get_response
    response = wrapped_callback(request, *callback_args, **callback_kwargs)
  File "/Library/Frameworks/Python.framework/Versions/3.13/lib/python3.13/site-packages/django/contrib/auth/decorators.py", line 60, in _view_wrapper
    return view_func(request, *args, **kwargs)
  File "/Users/danieloh/ssa_project/chipin/views.py", line 237, in group_detail
    user_eligible = request.user.profile.max_spend >= event_share
                    ^^^^^^^^^^^^^^^^^^^^
  File "/Library/Frameworks/Python.framework/Versions/3.13/lib/python3.13/site-packages/django/utils/functional.py", line 253, in inner
    return func(_wrapped, *args)
  File "/Library/Frameworks/Python.framework/Versions/3.13/lib/python3.13/site-packages/django/db/models/fields/related_descriptors.py", line 531, in __get__
    raise self.RelatedObjectDoesNotExist(
    ...<2 lines>...
    )
django.contrib.auth.models.User.profile.RelatedObjectDoesNotExist: User has no profile.
"GET /chipin/group/7/ HTTP/1.1" 500 77114
Internal Server Error: /chipin/group/7/
Traceback (most recent call last):
  File "/Library/Frameworks/Python.framework/Versions/3.13/lib/python3.13/site-packages/django/core/handlers/exception.py", line 55, in inner
    response = get_response(request)
  File "/Library/Frameworks/Python.framework/Versions/3.13/lib/python3.13/site-packages/django/core/handlers/base.py", line 197, in _get_response
    response = wrapped_callback(request, *callback_args, **callback_kwargs)
  File "/Library/Frameworks/Python.framework/Versions/3.13/lib/python3.13/site-packages/django/contrib/auth/decorators.py", line 60, in _view_wrapper
    return view_func(request, *args, **kwargs)
  File "/Users/danieloh/ssa_project/chipin/views.py", line 237, in group_detail
    user_eligible = request.user.profile.max_spend >= event_share
                    ^^^^^^^^^^^^^^^^^^^^
  File "/Library/Frameworks/Python.framework/Versions/3.13/lib/python3.13/site-packages/django/utils/functional.py", line 253, in inner
    return func(_wrapped, *args)
  File "/Library/Frameworks/Python.framework/Versions/3.13/lib/python3.13/site-packages/django/db/models/fields/related_descriptors.py", line 531, in __get__
    raise self.RelatedObjectDoesNotExist(
    ...<2 lines>...
    )
django.contrib.auth.models.User.profile.RelatedObjectDoesNotExist: User has no profile.
"GET /chipin/group/7/ HTTP/1.1" 500 76977
Internal Server Error: /chipin/group/7/
Traceback (most recent call last):
  File "/Library/Frameworks/Python.framework/Versions/3.13/lib/python3.13/site-packages/django/core/handlers/exception.py", line 55, in inner
    response = get_response(request)
  File "/Library/Frameworks/Python.framework/Versions/3.13/lib/python3.13/site-packages/django/core/handlers/base.py", line 197, in _get_response
    response = wrapped_callback(request, *callback_args, **callback_kwargs)
  File "/Library/Frameworks/Python.framework/Versions/3.13/lib/python3.13/site-packages/django/contrib/auth/decorators.py", line 60, in _view_wrapper
    return view_func(request, *args, **kwargs)
  File "/Users/danieloh/ssa_project/chipin/views.py", line 237, in group_detail
    user_eligible = request.user.profile.max_spend >= event_share
                    ^^^^^^^^^^^^^^^^^^^^
  File "/Library/Frameworks/Python.framework/Versions/3.13/lib/python3.13/site-packages/django/utils/functional.py", line 253, in inner
    return func(_wrapped, *args)
  File "/Library/Frameworks/Python.framework/Versions/3.13/lib/python3.13/site-packages/django/db/models/fields/related_descriptors.py", line 531, in __get__
    raise self.RelatedObjectDoesNotExist(
    ...<2 lines>...
    )
django.contrib.auth.models.User.profile.RelatedObjectDoesNotExist: User has no profile.
"GET /chipin/group/7/ HTTP/1.1" 500 76669
Internal Server Error: /chipin/group/7/
Traceback (most recent call last):
  File "/Library/Frameworks/Python.framework/Versions/3.13/lib/python3.13/site-packages/django/core/handlers/exception.py", line 55, in inner
    response = get_response(request)
  File "/Library/Frameworks/Python.framework/Versions/3.13/lib/python3.13/site-packages/django/core/handlers/base.py", line 197, in _get_response
    response = wrapped_callback(request, *callback_args, **callback_kwargs)
  File "/Library/Frameworks/Python.framework/Versions/3.13/lib/python3.13/site-packages/django/contrib/auth/decorators.py", line 60, in _view_wrapper
    return view_func(request, *args, **kwargs)
  File "/Users/danieloh/ssa_project/chipin/views.py", line 237, in group_detail
    user_eligible = request.user.profile.max_spend >= event_share
                    ^^^^^^^^^^^^^^^^^^^^
  File "/Library/Frameworks/Python.framework/Versions/3.13/lib/python3.13/site-packages/django/utils/functional.py", line 253, in inner
    return func(_wrapped, *args)
  File "/Library/Frameworks/Python.framework/Versions/3.13/lib/python3.13/site-packages/django/db/models/fields/related_descriptors.py", line 531, in __get__
    raise self.RelatedObjectDoesNotExist(
    ...<2 lines>...
    )
django.contrib.auth.models.User.profile.RelatedObjectDoesNotExist: User has no profile.
"GET /chipin/group/7/ HTTP/1.1" 500 76669
Internal Server Error: /chipin/group/7/
Traceback (most recent call last):
  File "/Library/Frameworks/Python.framework/Versions/3.13/lib/python3.13/site-packages/django/core/handlers/exception.py", line 55, in inner
    response = get_response(request)
  File "/Library/Frameworks/Python.framework/Versions/3.13/lib/python3.13/site-packages/django/core/handlers/base.py", line 197, in _get_response
    response = wrapped_callback(request, *callback_args, **callback_kwargs)
  File "/Library/Frameworks/Python.framework/Versions/3.13/lib/python3.13/site-packages/django/contrib/auth/decorators.py", line 60, in _view_wrapper
    return view_func(request, *args, **kwargs)
  File "/Users/danieloh/ssa_project/chipin/views.py", line 237, in group_detail
    user_eligible = request.user.profile.max_spend >= event_share
                    ^^^^^^^^^^^^^^^^^^^^
  File "/Library/Frameworks/Python.framework/Versions/3.13/lib/python3.13/site-packages/django/utils/functional.py", line 253, in inner
    return func(_wrapped, *args)
  File "/Library/Frameworks/Python.framework/Versions/3.13/lib/python3.13/site-packages/django/db/models/fields/related_descriptors.py", line 531, in __get__
    raise self.RelatedObjectDoesNotExist(
    ...<2 lines>...
    )
django.contrib.auth.models.User.profile.RelatedObjectDoesNotExist: User has no profile.
"GET /chipin/group/7/ HTTP/1.1" 500 76669
Internal Server Error: /chipin/group/7/
Traceback (most recent call last):
  File "/Library/Frameworks/Python.framework/Versions/3.13/lib/python3.13/site-packages/django/core/handlers/exception.py", line 55, in inner
    response = get_response(request)
  File "/Library/Frameworks/Python.framework/Versions/3.13/lib/python3.13/site-packages/django/core/handlers/base.py", line 197, in _get_response
    response = wrapped_callback(request, *callback_args, **callback_kwargs)
  File "/Library/Frameworks/Python.framework/Versions/3.13/lib/python3.13/site-packages/django/contrib/auth/decorators.py", line 60, in _view_wrapper
    return view_func(request, *args, **kwargs)
  File "/Users/danieloh/ssa_project/chipin/views.py", line 237, in group_detail
    user_eligible = request.user.profile.max_spend >= event_share
                    ^^^^^^^^^^^^^^^^^^^^
  File "/Library/Frameworks/Python.framework/Versions/3.13/lib/python3.13/site-packages/django/utils/functional.py", line 253, in inner
    return func(_wrapped, *args)
  File "/Library/Frameworks/Python.framework/Versions/3.13/lib/python3.13/site-packages/django/db/models/fields/related_descriptors.py", line 531, in __get__
    raise self.RelatedObjectDoesNotExist(
    ...<2 lines>...
    )
django.contrib.auth.models.User.profile.RelatedObjectDoesNotExist: User has no profile.
"GET /chipin/group/7/ HTTP/1.1" 500 76669
Internal Server Error: /chipin/group/7/
Traceback (most recent call last):
  File "/Library/Frameworks/Python.framework/Versions/3.13/lib/python3.13/site-packages/django/core/handlers/exception.py", line 55, in inner
    response = get_response(request)
  File "/Library/Frameworks/Python.framework/Versions/3.13/lib/python3.13/site-packages/django/core/handlers/base.py", line 197, in _get_response
    response = wrapped_callback(request, *callback_args, **callback_kwargs)
  File "/Library/Frameworks/Python.framework/Versions/3.13/lib/python3.13/site-packages/django/contrib/auth/decorators.py", line 60, in _view_wrapper
    return view_func(request, *args, **kwargs)
  File "/Users/danieloh/ssa_project/chipin/views.py", line 43, in group_detail
    user_eligible = request.user.profile.max_spend >= event_share
                    ^^^^^^^^^^^^^^^^^^^^
  File "/Library/Frameworks/Python.framework/Versions/3.13/lib/python3.13/site-packages/django/utils/functional.py", line 253, in inner
    return func(_wrapped, *args)
  File "/Library/Frameworks/Python.framework/Versions/3.13/lib/python3.13/site-packages/django/db/models/fields/related_descriptors.py", line 531, in __get__
    raise self.RelatedObjectDoesNotExist(
    ...<2 lines>...
    )
django.contrib.auth.models.User.profile.RelatedObjectDoesNotExist: User has no profile.
"GET /chipin/group/7/ HTTP/1.1" 500 76663
Internal Server Error: /chipin/group/8/
Traceback (most recent call last):
  File "/Library/Frameworks/Python.framework/Versions/3.13/lib/python3.13/site-packages/django/core/handlers/exception.py", line 55, in inner
    response = get_response(request)
  File "/Library/Frameworks/Python.framework/Versions/3.13/lib/python3.13/site-packages/django/core/handlers/base.py", line 197, in _get_response
    response = wrapped_callback(request, *callback_args, **callback_kwargs)
  File "/Library/Frameworks/Python.framework/Versions/3.13/lib/python3.13/site-packages/django/contrib/auth/decorators.py", line 60, in _view_wrapper
    return view_func(request, *args, **kwargs)
  File "/Users/danieloh/ssa_project/chipin/views.py", line 43, in group_detail
    user_eligible = request.user.profile.max_spend >= event_share
                    ^^^^^^^^^^^^^^^^^^^^
  File "/Library/Frameworks/Python.framework/Versions/3.13/lib/python3.13/site-packages/django/utils/functional.py", line 253, in inner
    return func(_wrapped, *args)
  File "/Library/Frameworks/Python.framework/Versions/3.13/lib/python3.13/site-packages/django/db/models/fields/related_descriptors.py", line 531, in __get__
    raise self.RelatedObjectDoesNotExist(
    ...<2 lines>...
    )
django.contrib.auth.models.User.profile.RelatedObjectDoesNotExist: User has no profile.
"GET /chipin/group/8/ HTTP/1.1" 500 77036
Internal Server Error: /chipin/group/8/
Traceback (most recent call last):
  File "/Library/Frameworks/Python.framework/Versions/3.13/lib/python3.13/site-packages/django/core/handlers/exception.py", line 55, in inner
    response = get_response(request)
  File "/Library/Frameworks/Python.framework/Versions/3.13/lib/python3.13/site-packages/django/core/handlers/base.py", line 197, in _get_response
    response = wrapped_callback(request, *callback_args, **callback_kwargs)
  File "/Library/Frameworks/Python.framework/Versions/3.13/lib/python3.13/site-packages/django/contrib/auth/decorators.py", line 60, in _view_wrapper
    return view_func(request, *args, **kwargs)
  File "/Users/danieloh/ssa_project/chipin/views.py", line 43, in group_detail
    user_eligible = request.user.profile.max_spend >= event_share
                    ^^^^^^^^^^^^^^^^^^^^
  File "/Library/Frameworks/Python.framework/Versions/3.13/lib/python3.13/site-packages/django/utils/functional.py", line 253, in inner
    return func(_wrapped, *args)
  File "/Library/Frameworks/Python.framework/Versions/3.13/lib/python3.13/site-packages/django/db/models/fields/related_descriptors.py", line 531, in __get__
    raise self.RelatedObjectDoesNotExist(
    ...<2 lines>...
    )
django.contrib.auth.models.User.profile.RelatedObjectDoesNotExist: User has no profile.
"GET /chipin/group/8/ HTTP/1.1" 500 76622
Internal Server Error: /chipin/group/8/
Traceback (most recent call last):
  File "/Library/Frameworks/Python.framework/Versions/3.13/lib/python3.13/site-packages/django/core/handlers/exception.py", line 55, in inner
    response = get_response(request)
  File "/Library/Frameworks/Python.framework/Versions/3.13/lib/python3.13/site-packages/django/core/handlers/base.py", line 197, in _get_response
    response = wrapped_callback(request, *callback_args, **callback_kwargs)
  File "/Library/Frameworks/Python.framework/Versions/3.13/lib/python3.13/site-packages/django/contrib/auth/decorators.py", line 60, in _view_wrapper
    return view_func(request, *args, **kwargs)
  File "/Users/danieloh/ssa_project/chipin/views.py", line 43, in group_detail
    user_eligible = request.user.profile.max_spend >= event_share
                    ^^^^^^^^^^^^^^^^^^^^
  File "/Library/Frameworks/Python.framework/Versions/3.13/lib/python3.13/site-packages/django/utils/functional.py", line 253, in inner
    return func(_wrapped, *args)
  File "/Library/Frameworks/Python.framework/Versions/3.13/lib/python3.13/site-packages/django/db/models/fields/related_descriptors.py", line 531, in __get__
    raise self.RelatedObjectDoesNotExist(
    ...<2 lines>...
    )
django.contrib.auth.models.User.profile.RelatedObjectDoesNotExist: User has no profile.
"GET /chipin/group/8/ HTTP/1.1" 500 76601
Internal Server Error: /chipin/group/8/
Traceback (most recent call last):
  File "/Library/Frameworks/Python.framework/Versions/3.13/lib/python3.13/site-packages/django/core/handlers/exception.py", line 55, in inner
    response = get_response(request)
  File "/Library/Frameworks/Python.framework/Versions/3.13/lib/python3.13/site-packages/django/core/handlers/base.py", line 197, in _get_response
    response = wrapped_callback(request, *callback_args, **callback_kwargs)
  File "/Library/Frameworks/Python.framework/Versions/3.13/lib/python3.13/site-packages/django/contrib/auth/decorators.py", line 60, in _view_wrapper
    return view_func(request, *args, **kwargs)
  File "/Users/danieloh/ssa_project/chipin/views.py", line 43, in group_detail
    user_eligible = request.user.profile.max_spend >= event_share
                    ^^^^^^^^^^^^^^^^^^^^
  File "/Library/Frameworks/Python.framework/Versions/3.13/lib/python3.13/site-packages/django/utils/functional.py", line 253, in inner
    return func(_wrapped, *args)
  File "/Library/Frameworks/Python.framework/Versions/3.13/lib/python3.13/site-packages/django/db/models/fields/related_descriptors.py", line 531, in __get__
    raise self.RelatedObjectDoesNotExist(
    ...<2 lines>...
    )
django.contrib.auth.models.User.profile.RelatedObjectDoesNotExist: User has no profile.
"GET /chipin/group/8/ HTTP/1.1" 500 76601
Internal Server Error: /chipin/group/8/event/9/join/
Traceback (most recent call last):
  File "/Library/Frameworks/Python.framework/Versions/3.13/lib/python3.13/site-packages/django/core/handlers/exception.py", line 55, in inner
    response = get_response(request)
  File "/Library/Frameworks/Python.framework/Versions/3.13/lib/python3.13/site-packages/django/core/handlers/base.py", line 197, in _get_response
    response = wrapped_callback(request, *callback_args, **callback_kwargs)
  File "/Library/Frameworks/Python.framework/Versions/3.13/lib/python3.13/site-packages/django/contrib/auth/decorators.py", line 60, in _view_wrapper
    return view_func(request, *args, **kwargs)
  File "/Users/danieloh/ssa_project/chipin/views.py", line 273, in join_event
    event.check_status()
    ~~~~~~~~~~~~~~~~~~^^
  File "/Users/danieloh/ssa_project/chipin/models.py", line 48, in check_status
    if member.profile.max_spend < share:
       ^^^^^^^^^^^^^^
  File "/Library/Frameworks/Python.framework/Versions/3.13/lib/python3.13/site-packages/django/db/models/fields/related_descriptors.py", line 531, in __get__
    raise self.RelatedObjectDoesNotExist(
    ...<2 lines>...
    )
django.contrib.auth.models.User.profile.RelatedObjectDoesNotExist: User has no profile.
"GET /chipin/group/8/event/9/join/ HTTP/1.1" 500 75298
Internal Server Error: /chipin/group/9/invite/
Traceback (most recent call last):
  File "/Library/Frameworks/Python.framework/Versions/3.13/lib/python3.13/site-packages/django/core/handlers/exception.py", line 55, in inner
    response = get_response(request)
  File "/Library/Frameworks/Python.framework/Versions/3.13/lib/python3.13/site-packages/django/core/handlers/base.py", line 197, in _get_response
    response = wrapped_callback(request, *callback_args, **callback_kwargs)
  File "/Library/Frameworks/Python.framework/Versions/3.13/lib/python3.13/site-packages/django/contrib/auth/decorators.py", line 60, in _view_wrapper
    return view_func(request, *args, **kwargs)
  File "/Users/danieloh/ssa_project/chipin/views.py", line 112, in invite_users
    messages.success(request, f'Invitation sent to {invited_user.profile.nickname}.')
                                                    ^^^^^^^^^^^^^^^^^^^^
  File "/Library/Frameworks/Python.framework/Versions/3.13/lib/python3.13/site-packages/django/db/models/fields/related_descriptors.py", line 531, in __get__
    raise self.RelatedObjectDoesNotExist(
    ...<2 lines>...
    )
django.contrib.auth.models.User.profile.RelatedObjectDoesNotExist: User has no profile.
"POST /chipin/group/9/invite/ HTTP/1.1" 500 72857
Internal Server Error: /chipin/group/9/invite/
Traceback (most recent call last):
  File "/Library/Frameworks/Python.framework/Versions/3.13/lib/python3.13/site-packages/django/core/handlers/exception.py", line 55, in inner
    response = get_response(request)
  File "/Library/Frameworks/Python.framework/Versions/3.13/lib/python3.13/site-packages/django/core/handlers/base.py", line 197, in _get_response
    response = wrapped_callback(request, *callback_args, **callback_kwargs)
  File "/Library/Frameworks/Python.framework/Versions/3.13/lib/python3.13/site-packages/django/contrib/auth/decorators.py", line 60, in _view_wrapper
    return view_func(request, *args, **kwargs)
  File "/Users/danieloh/ssa_project/chipin/views.py", line 109, in invite_users
    messages.info(request, f'{invited_user.profile.nickname} has already been invited.')
                              ^^^^^^^^^^^^^^^^^^^^
  File "/Library/Frameworks/Python.framework/Versions/3.13/lib/python3.13/site-packages/django/db/models/fields/related_descriptors.py", line 531, in __get__
    raise self.RelatedObjectDoesNotExist(
    ...<2 lines>...
    )
django.contrib.auth.models.User.profile.RelatedObjectDoesNotExist: User has no profile.
"POST /chipin/group/9/invite/ HTTP/1.1" 500 72943
